Workbook

Sheet DATOS
C1: Nombre Ingeniero responsable | D1: CIP
A2: INGRESO | C2: Carlos Gabriel Mego Armas | D2: 98925 | F2: ANULADO
A3: SALIDA | C3: Carlos Alberto Aguirre Jimenez | D3: 208575 | F3: CONFORME
C4: Víctor Manuel Soto Delgado | D4: 93951
A5: NO PELIGROSO
A6: PELIGROSO
B8: PELIGROSO | C8: PELIGROSO | D8: PELIGROSO | E8: PELIGROSO | F8: PELIGROSO | G8: PELIGROSO | H8: PELIGROSO | I8: PELIGROSO | J8: PELIGROSO | K8: PELIGROSO | L8: PELIGROSO | M8: PELIGROSO | N8: PELIGROSO | O8: PELIGROSO | P8: PELIGROSO | Q8: PELIGROSO | R8: PELIGROSO | S8: PELIGROSO | T8: PELIGROSO | U8: PELIGROSO | V8: PELIGROSO | W8: PELIGROSO | X8: PELIGROSO | Y8: PELIGROSO | Z8: PELIGROSO | AA8: PELIGROSO | AB8: PELIGROSO | AC8: PELIGROSO | AD8: PELIGROSO | AE8: PELIGROSO | AF8: NO PELIGROSO | AG8: NO PELIGROSO | AH8: NO PELIGROSO | AI8: NO PELIGROSO | AJ8: NO PELIGROSO | AK8: NO PELIGROSO | AL8: NO PELIGROSO | AM8: NO PELIGROSO
B9: ACEITE USADO | C9: ACEITE USADO DOMÉSTICO | D9: ACEITE VEGETAL USADO | E9: AGUA CON HIDROCARBUROS | F9: AGUAS RESIDUALES DOMÉSTICAS | G9: BATERÍAS USADAS | H9: BOLSAS DE CEMENTO VACIAS | I9: FILTROS DE ACEITE USADOS | J9: FILTROS DE AIRE USADOS | K9: GRASA USADA | L9: LODOS DE PTARD | M9: MATERIAL IMPREGNADO CON HIDROCARBUROS | N9: MATERIAL IMPREGNADO CON PRODUCTOS QUÍMICOS | O9: RAEE-CAT.1:GRANDES ELECTRODOMÉSTICOS | P9: RAEE-CAT.10:MÁQUINAS EXPENDEDORAS | Q9: RAEE-CAT.2:PEQUEÑOS ELECTRODOMÉSTICOS | R9: RAEE-CAT.3:EQUIPOS DE INFORMÁTICA Y TELECOMUNICACIONES | S9: RAEE-CAT.4:APARATOS ELECTRÓNICOS DE CONSUMO | T9: RAEE-CAT.5:APARATOS DE ALUMBRADO | U9: RAEE-CAT.6:HERRAMIENTAS ELÉCTRICAS Y ELECTRÓNICAS | V9: RAEE-CAT.7:JUGUETES O EQUIPOS DEPORTIVOS Y DE TIEMPO LIBRE | W9: RAEE-CAT.8:APARATOS MÉDICOS | X9: RAEE-CAT.9:INSTRUMENTOS DE VIGILANCIA Y CONTROL | Y9: REACTIVOS VENCIDOS | Z9: RESIDUOS BIOCONTAMINADOS (UNIDAD MÉDICA) | AA9: RESIDUOS DE CONCENTRADOS DE MINERAL | AB9: RESIDUOS DE VOLADURA (BOLSAS BIG BAG) | AC9: RESIDUOS DE VOLADURA (CAJAS DE ACCESORIOS) | AD9: RESIDUOS ESPECIALES (UNIDAD MÉDICA) | AE9: TIERRA IMPREGNADA CON HIDROCARBUROS | AF9: CHATARRA | AG9: LLANTAS USADAS Y JEBE | AH9: MADERA | AI9: NO APROVECHABLES | AJ9: ORGÁNICOS | AK9: PAPEL Y CARTON | AL9: PLÁSTICOS | AM9: VIDRIO
A10: F10 | B10: =IF('F002'!#REF!="PELIGROSO",DATOS!$B$9,"") -> #REF! | C10: =IF('F002'!#REF!="PELIGROSO",DATOS!$C$9,"") -> #REF! | D10: =IF('F002'!#REF!="PELIGROSO",DATOS!$D$9,"") -> #REF! | E10: =IF('F002'!#REF!="PELIGROSO",DATOS!$E$9,"") -> #REF! | F10: =IF('F002'!#REF!="PELIGROSO",DATOS!$F$9,"") -> #REF! | G10: =IF('F002'!#REF!="PELIGROSO",DATOS!$G$9,"") -> #REF! | H10: =IF('F002'!#REF!="PELIGROSO",DATOS!$H$9,"") -> #REF! | I10: =IF('F002'!#REF!="PELIGROSO",DATOS!$I$9,"") -> #REF! | J10: =IF('F002'!#REF!="PELIGROSO",DATOS!$J$9,"") -> #REF! | K10: =IF('F002'!#REF!="PELIGROSO",DATOS!$K$9,"") -> #REF! | L10: =IF('F002'!#REF!="PELIGROSO",DATOS!$L$9,"") -> #REF! | M10: =IF('F002'!#REF!="PELIGROSO",DATOS!$M$9,"") -> #REF! | N10: =IF('F002'!#REF!="PELIGROSO",DATOS!$N$9,"") -> #REF! | O10: =IF('F002'!#REF!="PELIGROSO",DATOS!$O$9,"") -> #REF! | P10: =IF('F002'!#REF!="PELIGROSO",DATOS!$P$9,"") -> #REF! | Q10: =IF('F002'!#REF!="PELIGROSO",DATOS!$Q$9,"") -> #REF! | R10: =IF('F002'!#REF!="PELIGROSO",DATOS!$R$9,"") -> #REF! | S10: =IF('F002'!#REF!="PELIGROSO",DATOS!$S$9,"") -> #REF! | T10: =IF('F002'!#REF!="PELIGROSO",DATOS!$T$9,"") -> #REF! | U10: =IF('F002'!#REF!="PELIGROSO",DATOS!$U$9,"") -> #REF! | V10: =IF('F002'!#REF!="PELIGROSO",DATOS!$V$9,"") -> #REF! | W10: =IF('F002'!#REF!="PELIGROSO",DATOS!$W$9,"") -> #REF! | X10: =IF('F002'!#REF!="PELIGROSO",DATOS!$X$9,"") -> #REF! | Y10: =IF('F002'!#REF!="PELIGROSO",DATOS!$Y$9,"") -> #REF! | Z10: =IF('F002'!#REF!="PELIGROSO",DATOS!$Z$9,"") -> #REF! | AA10: =IF('F002'!#REF!="PELIGROSO",DATOS!$AA$9,"") -> #REF! | AB10: =IF('F002'!#REF!="PELIGROSO",DATOS!$AB$9,"") -> #REF! | AC10: =IF('F002'!#REF!="PELIGROSO",DATOS!$AC$9,"") -> #REF! | AD10: =IF('F002'!#REF!="PELIGROSO",DATOS!$AD$9,"") -> #REF! | AE10: =IF('F002'!#REF!="PELIGROSO",DATOS!$AE$9,"") -> #REF! | AF10: =IF('F002'!#REF!="NO PELIGROSO",DATOS!$AF$9,"") -> #REF! | AG10: =IF('F002'!#REF!="NO PELIGROSO",DATOS!$AG$9,"") -> #REF! | AH10: =IF('F002'!#REF!="NO PELIGROSO",DATOS!$AH$9,"") -> #REF! | AI10: =IF('F002'!#REF!="NO PELIGROSO",DATOS!$AI$9,"") -> #REF! | AJ10: =IF('F002'!#REF!="NO PELIGROSO",DATOS!$AJ$9,"") -> #REF! | AK10: =IF('F002'!#REF!="NO PELIGROSO",DATOS!$AK$9,"") -> #REF! | AL10: =IF('F002'!#REF!="NO PELIGROSO",DATOS!$AL$9,"") -> #REF! | AM10: =IF('F002'!#REF!="NO PELIGROSO",DATOS!$AM$9,"") -> #REF!
A11: F11 | B11: =IF('F002'!#REF!="PELIGROSO",DATOS!$B$9,"") -> #REF! | C11: =IF('F002'!#REF!="PELIGROSO",DATOS!$C$9,"") -> #REF! | D11: =IF('F002'!#REF!="PELIGROSO",DATOS!$D$9,"") -> #REF! | E11: =IF('F002'!#REF!="PELIGROSO",DATOS!$E$9,"") -> #REF! | F11: =IF('F002'!#REF!="PELIGROSO",DATOS!$F$9,"") -> #REF! | G11: =IF('F002'!#REF!="PELIGROSO",DATOS!$G$9,"") -> #REF! | H11: =IF('F002'!#REF!="PELIGROSO",DATOS!$H$9,"") -> #REF! | I11: =IF('F002'!#REF!="PELIGROSO",DATOS!$I$9,"") -> #REF! | J11: =IF('F002'!#REF!="PELIGROSO",DATOS!$J$9,"") -> #REF! | K11: =IF('F002'!#REF!="PELIGROSO",DATOS!$K$9,"") -> #REF! | L11: =IF('F002'!#REF!="PELIGROSO",DATOS!$L$9,"") -> #REF! | M11: =IF('F002'!#REF!="PELIGROSO",DATOS!$M$9,"") -> #REF! | N11: =IF('F002'!#REF!="PELIGROSO",DATOS!$N$9,"") -> #REF! | O11: =IF('F002'!#REF!="PELIGROSO",DATOS!$O$9,"") -> #REF! | P11: =IF('F002'!#REF!="PELIGROSO",DATOS!$P$9,"") -> #REF! | Q11: =IF('F002'!#REF!="PELIGROSO",DATOS!$Q$9,"") -> #REF! | R11: =IF('F002'!#REF!="PELIGROSO",DATOS!$R$9,"") -> #REF! | S11: =IF('F002'!#REF!="PELIGROSO",DATOS!$S$9,"") -> #REF! | T11: =IF('F002'!#REF!="PELIGROSO",DATOS!$T$9,"") -> #REF! | U11: =IF('F002'!#REF!="PELIGROSO",DATOS!$U$9,"") -> #REF! | V11: =IF('F002'!#REF!="PELIGROSO",DATOS!$V$9,"") -> #REF! | W11: =IF('F002'!#REF!="PELIGROSO",DATOS!$W$9,"") -> #REF! | X11: =IF('F002'!#REF!="PELIGROSO",DATOS!$X$9,"") -> #REF! | Y11: =IF('F002'!#REF!="PELIGROSO",DATOS!$Y$9,"") -> #REF! | Z11: =IF('F002'!#REF!="PELIGROSO",DATOS!$Z$9,"") -> #REF! | AA11: =IF('F002'!#REF!="PELIGROSO",DATOS!$AA$9,"") -> #REF! | AB11: =IF('F002'!#REF!="PELIGROSO",DATOS!$AB$9,"") -> #REF! | AC11: =IF('F002'!#REF!="PELIGROSO",DATOS!$AC$9,"") -> #REF! | AD11: =IF('F002'!#REF!="PELIGROSO",DATOS!$AD$9,"") -> #REF! | AE11: =IF('F002'!#REF!="PELIGROSO",DATOS!$AE$9,"") -> #REF! | AF11: =IF('F002'!#REF!="NO PELIGROSO",DATOS!$AF$9,"") -> #REF! | AG11: =IF('F002'!#REF!="NO PELIGROSO",DATOS!$AG$9,"") -> #REF! | AH11: =IF('F002'!#REF!="NO PELIGROSO",DATOS!$AH$9,"") -> #REF! | AI11: =IF('F002'!#REF!="NO PELIGROSO",DATOS!$AI$9,"") -> #REF! | AJ11: =IF('F002'!#REF!="NO PELIGROSO",DATOS!$AJ$9,"") -> #REF! | AK11: =IF('F002'!#REF!="NO PELIGROSO",DATOS!$AK$9,"") -> #REF! | AL11: =IF('F002'!#REF!="NO PELIGROSO",DATOS!$AL$9,"") -> #REF! | AM11: =IF('F002'!#REF!="NO PELIGROSO",DATOS!$AM$9,"") -> #REF!
A12: F12 | B12: =IF('F002'!#REF!="PELIGROSO",DATOS!$B$9,"") -> #REF! | C12: =IF('F002'!#REF!="PELIGROSO",DATOS!$C$9,"") -> #REF! | D12: =IF('F002'!#REF!="PELIGROSO",DATOS!$D$9,"") -> #REF! | E12: =IF('F002'!#REF!="PELIGROSO",DATOS!$E$9,"") -> #REF! | F12: =IF('F002'!#REF!="PELIGROSO",DATOS!$F$9,"") -> #REF! | G12: =IF('F002'!#REF!="PELIGROSO",DATOS!$G$9,"") -> #REF! | H12: =IF('F002'!#REF!="PELIGROSO",DATOS!$H$9,"") -> #REF! | I12: =IF('F002'!#REF!="PELIGROSO",DATOS!$I$9,"") -> #REF! | J12: =IF('F002'!#REF!="PELIGROSO",DATOS!$J$9,"") -> #REF! | K12: =IF('F002'!#REF!="PELIGROSO",DATOS!$K$9,"") -> #REF! | L12: =IF('F002'!#REF!="PELIGROSO",DATOS!$L$9,"") -> #REF! | M12: =IF('F002'!#REF!="PELIGROSO",DATOS!$M$9,"") -> #REF! | N12: =IF('F002'!#REF!="PELIGROSO",DATOS!$N$9,"") -> #REF! | O12: =IF('F002'!#REF!="PELIGROSO",DATOS!$O$9,"") -> #REF! | P12: =IF('F002'!#REF!="PELIGROSO",DATOS!$P$9,"") -> #REF! | Q12: =IF('F002'!#REF!="PELIGROSO",DATOS!$Q$9,"") -> #REF! | R12: =IF('F002'!#REF!="PELIGROSO",DATOS!$R$9,"") -> #REF! | S12: =IF('F002'!#REF!="PELIGROSO",DATOS!$S$9,"") -> #REF! | T12: =IF('F002'!#REF!="PELIGROSO",DATOS!$T$9,"") -> #REF! | U12: =IF('F002'!#REF!="PELIGROSO",DATOS!$U$9,"") -> #REF! | V12: =IF('F002'!#REF!="PELIGROSO",DATOS!$V$9,"") -> #REF! | W12: =IF('F002'!#REF!="PELIGROSO",DATOS!$W$9,"") -> #REF! | X12: =IF('F002'!#REF!="PELIGROSO",DATOS!$X$9,"") -> #REF! | Y12: =IF('F002'!#REF!="PELIGROSO",DATOS!$Y$9,"") -> #REF! | Z12: =IF('F002'!#REF!="PELIGROSO",DATOS!$Z$9,"") -> #REF! | AA12: =IF('F002'!#REF!="PELIGROSO",DATOS!$AA$9,"") -> #REF! | AB12: =IF('F002'!#REF!="PELIGROSO",DATOS!$AB$9,"") -> #REF! | AC12: =IF('F002'!#REF!="PELIGROSO",DATOS!$AC$9,"") -> #REF! | AD12: =IF('F002'!#REF!="PELIGROSO",DATOS!$AD$9,"") -> #REF! | AE12: =IF('F002'!#REF!="PELIGROSO",DATOS!$AE$9,"") -> #REF! | AF12: =IF('F002'!#REF!="NO PELIGROSO",DATOS!$AF$9,"") -> #REF! | AG12: =IF('F002'!#REF!="NO PELIGROSO",DATOS!$AG$9,"") -> #REF! | AH12: =IF('F002'!#REF!="NO PELIGROSO",DATOS!$AH$9,"") -> #REF! | AI12: =IF('F002'!#REF!="NO PELIGROSO",DATOS!$AI$9,"") -> #REF! | AJ12: =IF('F002'!#REF!="NO PELIGROSO",DATOS!$AJ$9,"") -> #REF! | AK12: =IF('F002'!#REF!="NO PELIGROSO",DATOS!$AK$9,"") -> #REF! | AL12: =IF('F002'!#REF!="NO PELIGROSO",DATOS!$AL$9,"") -> #REF! | AM12: =IF('F002'!#REF!="NO PELIGROSO",DATOS!$AM$9,"") -> #REF!
A13: F13 | B13: =IF('F002'!#REF!="PELIGROSO",DATOS!$B$9,"") -> #REF! | C13: =IF('F002'!#REF!="PELIGROSO",DATOS!$C$9,"") -> #REF! | D13: =IF('F002'!#REF!="PELIGROSO",DATOS!$D$9,"") -> #REF! | E13: =IF('F002'!#REF!="PELIGROSO",DATOS!$E$9,"") -> #REF! | F13: =IF('F002'!#REF!="PELIGROSO",DATOS!$F$9,"") -> #REF! | G13: =IF('F002'!#REF!="PELIGROSO",DATOS!$G$9,"") -> #REF! | H13: =IF('F002'!#REF!="PELIGROSO",DATOS!$H$9,"") -> #REF! | I13: =IF('F002'!#REF!="PELIGROSO",DATOS!$I$9,"") -> #REF! | J13: =IF('F002'!#REF!="PELIGROSO",DATOS!$J$9,"") -> #REF! | K13: =IF('F002'!#REF!="PELIGROSO",DATOS!$K$9,"") -> #REF! | L13: =IF('F002'!#REF!="PELIGROSO",DATOS!$L$9,"") -> #REF! | M13: =IF('F002'!#REF!="PELIGROSO",DATOS!$M$9,"") -> #REF! | N13: =IF('F002'!#REF!="PELIGROSO",DATOS!$N$9,"") -> #REF! | O13: =IF('F002'!#REF!="PELIGROSO",DATOS!$O$9,"") -> #REF! | P13: =IF('F002'!#REF!="PELIGROSO",DATOS!$P$9,"") -> #REF! | Q13: =IF('F002'!#REF!="PELIGROSO",DATOS!$Q$9,"") -> #REF! | R13: =IF('F002'!#REF!="PELIGROSO",DATOS!$R$9,"") -> #REF! | S13: =IF('F002'!#REF!="PELIGROSO",DATOS!$S$9,"") -> #REF! | T13: =IF('F002'!#REF!="PELIGROSO",DATOS!$T$9,"") -> #REF! | U13: =IF('F002'!#REF!="PELIGROSO",DATOS!$U$9,"") -> #REF! | V13: =IF('F002'!#REF!="PELIGROSO",DATOS!$V$9,"") -> #REF! | W13: =IF('F002'!#REF!="PELIGROSO",DATOS!$W$9,"") -> #REF! | X13: =IF('F002'!#REF!="PELIGROSO",DATOS!$X$9,"") -> #REF! | Y13: =IF('F002'!#REF!="PELIGROSO",DATOS!$Y$9,"") -> #REF! | Z13: =IF('F002'!#REF!="PELIGROSO",DATOS!$Z$9,"") -> #REF! | AA13: =IF('F002'!#REF!="PELIGROSO",DATOS!$AA$9,"") -> #REF! | AB13: =IF('F002'!#REF!="PELIGROSO",DATOS!$AB$9,"") -> #REF! | AC13: =IF('F002'!#REF!="PELIGROSO",DATOS!$AC$9,"") -> #REF! | AD13: =IF('F002'!#REF!="PELIGROSO",DATOS!$AD$9,"") -> #REF! | AE13: =IF('F002'!#REF!="PELIGROSO",DATOS!$AE$9,"") -> #REF! | AF13: =IF('F002'!#REF!="NO PELIGROSO",DATOS!$AF$9,"") -> #REF! | AG13: =IF('F002'!#REF!="NO PELIGROSO",DATOS!$AG$9,"") -> #REF! | AH13: =IF('F002'!#REF!="NO PELIGROSO",DATOS!$AH$9,"") -> #REF! | AI13: =IF('F002'!#REF!="NO PELIGROSO",DATOS!$AI$9,"") -> #REF! | AJ13: =IF('F002'!#REF!="NO PELIGROSO",DATOS!$AJ$9,"") -> #REF! | AK13: =IF('F002'!#REF!="NO PELIGROSO",DATOS!$AK$9,"") -> #REF! | AL13: =IF('F002'!#REF!="NO PELIGROSO",DATOS!$AL$9,"") -> #REF! | AM13: =IF('F002'!#REF!="NO PELIGROSO",DATOS!$AM$9,"") -> #REF!
A14: F14 | B14: =IF('F002'!#REF!="PELIGROSO",DATOS!$B$9,"") -> #REF! | C14: =IF('F002'!#REF!="PELIGROSO",DATOS!$C$9,"") -> #REF! | D14: =IF('F002'!#REF!="PELIGROSO",DATOS!$D$9,"") -> #REF! | E14: =IF('F002'!#REF!="PELIGROSO",DATOS!$E$9,"") -> #REF! | F14: =IF('F002'!#REF!="PELIGROSO",DATOS!$F$9,"") -> #REF! | G14: =IF('F002'!#REF!="PELIGROSO",DATOS!$G$9,"") -> #REF! | H14: =IF('F002'!#REF!="PELIGROSO",DATOS!$H$9,"") -> #REF! | I14: =IF('F002'!#REF!="PELIGROSO",DATOS!$I$9,"") -> #REF! | J14: =IF('F002'!#REF!="PELIGROSO",DATOS!$J$9,"") -> #REF! | K14: =IF('F002'!#REF!="PELIGROSO",DATOS!$K$9,"") -> #REF! | L14: =IF('F002'!#REF!="PELIGROSO",DATOS!$L$9,"") -> #REF! | M14: =IF('F002'!#REF!="PELIGROSO",DATOS!$M$9,"") -> #REF! | N14: =IF('F002'!#REF!="PELIGROSO",DATOS!$N$9,"") -> #REF! | O14: =IF('F002'!#REF!="PELIGROSO",DATOS!$O$9,"") -> #REF! | P14: =IF('F002'!#REF!="PELIGROSO",DATOS!$P$9,"") -> #REF! | Q14: =IF('F002'!#REF!="PELIGROSO",DATOS!$Q$9,"") -> #REF! | R14: =IF('F002'!#REF!="PELIGROSO",DATOS!$R$9,"") -> #REF! | S14: =IF('F002'!#REF!="PELIGROSO",DATOS!$S$9,"") -> #REF! | T14: =IF('F002'!#REF!="PELIGROSO",DATOS!$T$9,"") -> #REF! | U14: =IF('F002'!#REF!="PELIGROSO",DATOS!$U$9,"") -> #REF! | V14: =IF('F002'!#REF!="PELIGROSO",DATOS!$V$9,"") -> #REF! | W14: =IF('F002'!#REF!="PELIGROSO",DATOS!$W$9,"") -> #REF! | X14: =IF('F002'!#REF!="PELIGROSO",DATOS!$X$9,"") -> #REF! | Y14: =IF('F002'!#REF!="PELIGROSO",DATOS!$Y$9,"") -> #REF! | Z14: =IF('F002'!#REF!="PELIGROSO",DATOS!$Z$9,"") -> #REF! | AA14: =IF('F002'!#REF!="PELIGROSO",DATOS!$AA$9,"") -> #REF! | AB14: =IF('F002'!#REF!="PELIGROSO",DATOS!$AB$9,"") -> #REF! | AC14: =IF('F002'!#REF!="PELIGROSO",DATOS!$AC$9,"") -> #REF! | AD14: =IF('F002'!#REF!="PELIGROSO",DATOS!$AD$9,"") -> #REF! | AE14: =IF('F002'!#REF!="PELIGROSO",DATOS!$AE$9,"") -> #REF! | AF14: =IF('F002'!#REF!="NO PELIGROSO",DATOS!$AF$9,"") -> #REF! | AG14: =IF('F002'!#REF!="NO PELIGROSO",DATOS!$AG$9,"") -> #REF! | AH14: =IF('F002'!#REF!="NO PELIGROSO",DATOS!$AH$9,"") -> #REF! | AI14: =IF('F002'!#REF!="NO PELIGROSO",DATOS!$AI$9,"") -> #REF! | AJ14: =IF('F002'!#REF!="NO PELIGROSO",DATOS!$AJ$9,"") -> #REF! | AK14: =IF('F002'!#REF!="NO PELIGROSO",DATOS!$AK$9,"") -> #REF! | AL14: =IF('F002'!#REF!="NO PELIGROSO",DATOS!$AL$9,"") -> #REF! | AM14: =IF('F002'!#REF!="NO PELIGROSO",DATOS!$AM$9,"") -> #REF!
A15: F15 | B15: =IF('F002'!#REF!="PELIGROSO",DATOS!$B$9,"") -> #REF! | C15: =IF('F002'!#REF!="PELIGROSO",DATOS!$C$9,"") -> #REF! | D15: =IF('F002'!#REF!="PELIGROSO",DATOS!$D$9,"") -> #REF! | E15: =IF('F002'!#REF!="PELIGROSO",DATOS!$E$9,"") -> #REF! | F15: =IF('F002'!#REF!="PELIGROSO",DATOS!$F$9,"") -> #REF! | G15: =IF('F002'!#REF!="PELIGROSO",DATOS!$G$9,"") -> #REF! | H15: =IF('F002'!#REF!="PELIGROSO",DATOS!$H$9,"") -> #REF! | I15: =IF('F002'!#REF!="PELIGROSO",DATOS!$I$9,"") -> #REF! | J15: =IF('F002'!#REF!="PELIGROSO",DATOS!$J$9,"") -> #REF! | K15: =IF('F002'!#REF!="PELIGROSO",DATOS!$K$9,"") -> #REF! | L15: =IF('F002'!#REF!="PELIGROSO",DATOS!$L$9,"") -> #REF! | M15: =IF('F002'!#REF!="PELIGROSO",DATOS!$M$9,"") -> #REF! | N15: =IF('F002'!#REF!="PELIGROSO",DATOS!$N$9,"") -> #REF! | O15: =IF('F002'!#REF!="PELIGROSO",DATOS!$O$9,"") -> #REF! | P15: =IF('F002'!#REF!="PELIGROSO",DATOS!$P$9,"") -> #REF! | Q15: =IF('F002'!#REF!="PELIGROSO",DATOS!$Q$9,"") -> #REF! | R15: =IF('F002'!#REF!="PELIGROSO",DATOS!$R$9,"") -> #REF! | S15: =IF('F002'!#REF!="PELIGROSO",DATOS!$S$9,"") -> #REF! | T15: =IF('F002'!#REF!="PELIGROSO",DATOS!$T$9,"") -> #REF! | U15: =IF('F002'!#REF!="PELIGROSO",DATOS!$U$9,"") -> #REF! | V15: =IF('F002'!#REF!="PELIGROSO",DATOS!$V$9,"") -> #REF! | W15: =IF('F002'!#REF!="PELIGROSO",DATOS!$W$9,"") -> #REF! | X15: =IF('F002'!#REF!="PELIGROSO",DATOS!$X$9,"") -> #REF! | Y15: =IF('F002'!#REF!="PELIGROSO",DATOS!$Y$9,"") -> #REF! | Z15: =IF('F002'!#REF!="PELIGROSO",DATOS!$Z$9,"") -> #REF! | AA15: =IF('F002'!#REF!="PELIGROSO",DATOS!$AA$9,"") -> #REF! | AB15: =IF('F002'!#REF!="PELIGROSO",DATOS!$AB$9,"") -> #REF! | AC15: =IF('F002'!#REF!="PELIGROSO",DATOS!$AC$9,"") -> #REF! | AD15: =IF('F002'!#REF!="PELIGROSO",DATOS!$AD$9,"") -> #REF! | AE15: =IF('F002'!#REF!="PELIGROSO",DATOS!$AE$9,"") -> #REF! | AF15: =IF('F002'!#REF!="NO PELIGROSO",DATOS!$AF$9,"") -> #REF! | AG15: =IF('F002'!#REF!="NO PELIGROSO",DATOS!$AG$9,"") -> #REF! | AH15: =IF('F002'!#REF!="NO PELIGROSO",DATOS!$AH$9,"") -> #REF! | AI15: =IF('F002'!#REF!="NO PELIGROSO",DATOS!$AI$9,"") -> #REF! | AJ15: =IF('F002'!#REF!="NO PELIGROSO",DATOS!$AJ$9,"") -> #REF! | AK15: =IF('F002'!#REF!="NO PELIGROSO",DATOS!$AK$9,"") -> #REF! | AL15: =IF('F002'!#REF!="NO PELIGROSO",DATOS!$AL$9,"") -> #REF! | AM15: =IF('F002'!#REF!="NO PELIGROSO",DATOS!$AM$9,"") -> #REF!
A16: F16 | B16: =IF('F002'!#REF!="PELIGROSO",DATOS!$B$9,"") -> #REF! | C16: =IF('F002'!#REF!="PELIGROSO",DATOS!$C$9,"") -> #REF! | D16: =IF('F002'!#REF!="PELIGROSO",DATOS!$D$9,"") -> #REF! | E16: =IF('F002'!#REF!="PELIGROSO",DATOS!$E$9,"") -> #REF! | F16: =IF('F002'!#REF!="PELIGROSO",DATOS!$F$9,"") -> #REF! | G16: =IF('F002'!#REF!="PELIGROSO",DATOS!$G$9,"") -> #REF! | H16: =IF('F002'!#REF!="PELIGROSO",DATOS!$H$9,"") -> #REF! | I16: =IF('F002'!#REF!="PELIGROSO",DATOS!$I$9,"") -> #REF! | J16: =IF('F002'!#REF!="PELIGROSO",DATOS!$J$9,"") -> #REF! | K16: =IF('F002'!#REF!="PELIGROSO",DATOS!$K$9,"") -> #REF! | L16: =IF('F002'!#REF!="PELIGROSO",DATOS!$L$9,"") -> #REF! | M16: =IF('F002'!#REF!="PELIGROSO",DATOS!$M$9,"") -> #REF! | N16: =IF('F002'!#REF!="PELIGROSO",DATOS!$N$9,"") -> #REF! | O16: =IF('F002'!#REF!="PELIGROSO",DATOS!$O$9,"") -> #REF! | P16: =IF('F002'!#REF!="PELIGROSO",DATOS!$P$9,"") -> #REF! | Q16: =IF('F002'!#REF!="PELIGROSO",DATOS!$Q$9,"") -> #REF! | R16: =IF('F002'!#REF!="PELIGROSO",DATOS!$R$9,"") -> #REF! | S16: =IF('F002'!#REF!="PELIGROSO",DATOS!$S$9,"") -> #REF! | T16: =IF('F002'!#REF!="PELIGROSO",DATOS!$T$9,"") -> #REF! | U16: =IF('F002'!#REF!="PELIGROSO",DATOS!$U$9,"") -> #REF! | V16: =IF('F002'!#REF!="PELIGROSO",DATOS!$V$9,"") -> #REF! | W16: =IF('F002'!#REF!="PELIGROSO",DATOS!$W$9,"") -> #REF! | X16: =IF('F002'!#REF!="PELIGROSO",DATOS!$X$9,"") -> #REF! | Y16: =IF('F002'!#REF!="PELIGROSO",DATOS!$Y$9,"") -> #REF! | Z16: =IF('F002'!#REF!="PELIGROSO",DATOS!$Z$9,"") -> #REF! | AA16: =IF('F002'!#REF!="PELIGROSO",DATOS!$AA$9,"") -> #REF! | AB16: =IF('F002'!#REF!="PELIGROSO",DATOS!$AB$9,"") -> #REF! | AC16: =IF('F002'!#REF!="PELIGROSO",DATOS!$AC$9,"") -> #REF! | AD16: =IF('F002'!#REF!="PELIGROSO",DATOS!$AD$9,"") -> #REF! | AE16: =IF('F002'!#REF!="PELIGROSO",DATOS!$AE$9,"") -> #REF! | AF16: =IF('F002'!#REF!="NO PELIGROSO",DATOS!$AF$9,"") -> #REF! | AG16: =IF('F002'!#REF!="NO PELIGROSO",DATOS!$AG$9,"") -> #REF! | AH16: =IF('F002'!#REF!="NO PELIGROSO",DATOS!$AH$9,"") -> #REF! | AI16: =IF('F002'!#REF!="NO PELIGROSO",DATOS!$AI$9,"") -> #REF! | AJ16: =IF('F002'!#REF!="NO PELIGROSO",DATOS!$AJ$9,"") -> #REF! | AK16: =IF('F002'!#REF!="NO PELIGROSO",DATOS!$AK$9,"") -> #REF! | AL16: =IF('F002'!#REF!="NO PELIGROSO",DATOS!$AL$9,"") -> #REF! | AM16: =IF('F002'!#REF!="NO PELIGROSO",DATOS!$AM$9,"") -> #REF!
A17: F17 | B17: =IF('F002'!#REF!="PELIGROSO",DATOS!$B$9,"") -> #REF! | C17: =IF('F002'!#REF!="PELIGROSO",DATOS!$C$9,"") -> #REF! | D17: =IF('F002'!#REF!="PELIGROSO",DATOS!$D$9,"") -> #REF! | E17: =IF('F002'!#REF!="PELIGROSO",DATOS!$E$9,"") -> #REF! | F17: =IF('F002'!#REF!="PELIGROSO",DATOS!$F$9,"") -> #REF! | G17: =IF('F002'!#REF!="PELIGROSO",DATOS!$G$9,"") -> #REF! | H17: =IF('F002'!#REF!="PELIGROSO",DATOS!$H$9,"") -> #REF! | I17: =IF('F002'!#REF!="PELIGROSO",DATOS!$I$9,"") -> #REF! | J17: =IF('F002'!#REF!="PELIGROSO",DATOS!$J$9,"") -> #REF! | K17: =IF('F002'!#REF!="PELIGROSO",DATOS!$K$9,"") -> #REF! | L17: =IF('F002'!#REF!="PELIGROSO",DATOS!$L$9,"") -> #REF! | M17: =IF('F002'!#REF!="PELIGROSO",DATOS!$M$9,"") -> #REF! | N17: =IF('F002'!#REF!="PELIGROSO",DATOS!$N$9,"") -> #REF! | O17: =IF('F002'!#REF!="PELIGROSO",DATOS!$O$9,"") -> #REF! | P17: =IF('F002'!#REF!="PELIGROSO",DATOS!$P$9,"") -> #REF! | Q17: =IF('F002'!#REF!="PELIGROSO",DATOS!$Q$9,"") -> #REF! | R17: =IF('F002'!#REF!="PELIGROSO",DATOS!$R$9,"") -> #REF! | S17: =IF('F002'!#REF!="PELIGROSO",DATOS!$S$9,"") -> #REF! | T17: =IF('F002'!#REF!="PELIGROSO",DATOS!$T$9,"") -> #REF! | U17: =IF('F002'!#REF!="PELIGROSO",DATOS!$U$9,"") -> #REF! | V17: =IF('F002'!#REF!="PELIGROSO",DATOS!$V$9,"") -> #REF! | W17: =IF('F002'!#REF!="PELIGROSO",DATOS!$W$9,"") -> #REF! | X17: =IF('F002'!#REF!="PELIGROSO",DATOS!$X$9,"") -> #REF! | Y17: =IF('F002'!#REF!="PELIGROSO",DATOS!$Y$9,"") -> #REF! | Z17: =IF('F002'!#REF!="PELIGROSO",DATOS!$Z$9,"") -> #REF! | AA17: =IF('F002'!#REF!="PELIGROSO",DATOS!$AA$9,"") -> #REF! | AB17: =IF('F002'!#REF!="PELIGROSO",DATOS!$AB$9,"") -> #REF! | AC17: =IF('F002'!#REF!="PELIGROSO",DATOS!$AC$9,"") -> #REF! | AD17: =IF('F002'!#REF!="PELIGROSO",DATOS!$AD$9,"") -> #REF! | AE17: =IF('F002'!#REF!="PELIGROSO",DATOS!$AE$9,"") -> #REF! | AF17: =IF('F002'!#REF!="NO PELIGROSO",DATOS!$AF$9,"") -> #REF! | AG17: =IF('F002'!#REF!="NO PELIGROSO",DATOS!$AG$9,"") -> #REF! | AH17: =IF('F002'!#REF!="NO PELIGROSO",DATOS!$AH$9,"") -> #REF! | AI17: =IF('F002'!#REF!="NO PELIGROSO",DATOS!$AI$9,"") -> #REF! | AJ17: =IF('F002'!#REF!="NO PELIGROSO",DATOS!$AJ$9,"") -> #REF! | AK17: =IF('F002'!#REF!="NO PELIGROSO",DATOS!$AK$9,"") -> #REF! | AL17: =IF('F002'!#REF!="NO PELIGROSO",DATOS!$AL$9,"") -> #REF! | AM17: =IF('F002'!#REF!="NO PELIGROSO",DATOS!$AM$9,"") -> #REF!
A18: F18 | B18: =IF('F002'!#REF!="PELIGROSO",DATOS!$B$9,"") -> #REF! | C18: =IF('F002'!#REF!="PELIGROSO",DATOS!$C$9,"") -> #REF! | D18: =IF('F002'!#REF!="PELIGROSO",DATOS!$D$9,"") -> #REF! | E18: =IF('F002'!#REF!="PELIGROSO",DATOS!$E$9,"") -> #REF! | F18: =IF('F002'!#REF!="PELIGROSO",DATOS!$F$9,"") -> #REF! | G18: =IF('F002'!#REF!="PELIGROSO",DATOS!$G$9,"") -> #REF! | H18: =IF('F002'!#REF!="PELIGROSO",DATOS!$H$9,"") -> #REF! | I18: =IF('F002'!#REF!="PELIGROSO",DATOS!$I$9,"") -> #REF! | J18: =IF('F002'!#REF!="PELIGROSO",DATOS!$J$9,"") -> #REF! | K18: =IF('F002'!#REF!="PELIGROSO",DATOS!$K$9,"") -> #REF! | L18: =IF('F002'!#REF!="PELIGROSO",DATOS!$L$9,"") -> #REF! | M18: =IF('F002'!#REF!="PELIGROSO",DATOS!$M$9,"") -> #REF! | N18: =IF('F002'!#REF!="PELIGROSO",DATOS!$N$9,"") -> #REF! | O18: =IF('F002'!#REF!="PELIGROSO",DATOS!$O$9,"") -> #REF! | P18: =IF('F002'!#REF!="PELIGROSO",DATOS!$P$9,"") -> #REF! | Q18: =IF('F002'!#REF!="PELIGROSO",DATOS!$Q$9,"") -> #REF! | R18: =IF('F002'!#REF!="PELIGROSO",DATOS!$R$9,"") -> #REF! | S18: =IF('F002'!#REF!="PELIGROSO",DATOS!$S$9,"") -> #REF! | T18: =IF('F002'!#REF!="PELIGROSO",DATOS!$T$9,"") -> #REF! | U18: =IF('F002'!#REF!="PELIGROSO",DATOS!$U$9,"") -> #REF! | V18: =IF('F002'!#REF!="PELIGROSO",DATOS!$V$9,"") -> #REF! | W18: =IF('F002'!#REF!="PELIGROSO",DATOS!$W$9,"") -> #REF! | X18: =IF('F002'!#REF!="PELIGROSO",DATOS!$X$9,"") -> #REF! | Y18: =IF('F002'!#REF!="PELIGROSO",DATOS!$Y$9,"") -> #REF! | Z18: =IF('F002'!#REF!="PELIGROSO",DATOS!$Z$9,"") -> #REF! | AA18: =IF('F002'!#REF!="PELIGROSO",DATOS!$AA$9,"") -> #REF! | AB18: =IF('F002'!#REF!="PELIGROSO",DATOS!$AB$9,"") -> #REF! | AC18: =IF('F002'!#REF!="PELIGROSO",DATOS!$AC$9,"") -> #REF! | AD18: =IF('F002'!#REF!="PELIGROSO",DATOS!$AD$9,"") -> #REF! | AE18: =IF('F002'!#REF!="PELIGROSO",DATOS!$AE$9,"") -> #REF! | AF18: =IF('F002'!#REF!="NO PELIGROSO",DATOS!$AF$9,"") -> #REF! | AG18: =IF('F002'!#REF!="NO PELIGROSO",DATOS!$AG$9,"") -> #REF! | AH18: =IF('F002'!#REF!="NO PELIGROSO",DATOS!$AH$9,"") -> #REF! | AI18: =IF('F002'!#REF!="NO PELIGROSO",DATOS!$AI$9,"") -> #REF! | AJ18: =IF('F002'!#REF!="NO PELIGROSO",DATOS!$AJ$9,"") -> #REF! | AK18: =IF('F002'!#REF!="NO PELIGROSO",DATOS!$AK$9,"") -> #REF! | AL18: =IF('F002'!#REF!="NO PELIGROSO",DATOS!$AL$9,"") -> #REF! | AM18: =IF('F002'!#REF!="NO PELIGROSO",DATOS!$AM$9,"") -> #REF!
A19: F19 | B19: =IF('F002'!#REF!="PELIGROSO",DATOS!$B$9,"") -> #REF! | C19: =IF('F002'!#REF!="PELIGROSO",DATOS!$C$9,"") -> #REF! | D19: =IF('F002'!#REF!="PELIGROSO",DATOS!$D$9,"") -> #REF! | E19: =IF('F002'!#REF!="PELIGROSO",DATOS!$E$9,"") -> #REF! | F19: =IF('F002'!#REF!="PELIGROSO",DATOS!$F$9,"") -> #REF! | G19: =IF('F002'!#REF!="PELIGROSO",DATOS!$G$9,"") -> #REF! | H19: =IF('F002'!#REF!="PELIGROSO",DATOS!$H$9,"") -> #REF! | I19: =IF('F002'!#REF!="PELIGROSO",DATOS!$I$9,"") -> #REF! | J19: =IF('F002'!#REF!="PELIGROSO",DATOS!$J$9,"") -> #REF! | K19: =IF('F002'!#REF!="PELIGROSO",DATOS!$K$9,"") -> #REF! | L19: =IF('F002'!#REF!="PELIGROSO",DATOS!$L$9,"") -> #REF! | M19: =IF('F002'!#REF!="PELIGROSO",DATOS!$M$9,"") -> #REF! | N19: =IF('F002'!#REF!="PELIGROSO",DATOS!$N$9,"") -> #REF! | O19: =IF('F002'!#REF!="PELIGROSO",DATOS!$O$9,"") -> #REF! | P19: =IF('F002'!#REF!="PELIGROSO",DATOS!$P$9,"") -> #REF! | Q19: =IF('F002'!#REF!="PELIGROSO",DATOS!$Q$9,"") -> #REF! | R19: =IF('F002'!#REF!="PELIGROSO",DATOS!$R$9,"") -> #REF! | S19: =IF('F002'!#REF!="PELIGROSO",DATOS!$S$9,"") -> #REF! | T19: =IF('F002'!#REF!="PELIGROSO",DATOS!$T$9,"") -> #REF! | U19: =IF('F002'!#REF!="PELIGROSO",DATOS!$U$9,"") -> #REF! | V19: =IF('F002'!#REF!="PELIGROSO",DATOS!$V$9,"") -> #REF! | W19: =IF('F002'!#REF!="PELIGROSO",DATOS!$W$9,"") -> #REF! | X19: =IF('F002'!#REF!="PELIGROSO",DATOS!$X$9,"") -> #REF! | Y19: =IF('F002'!#REF!="PELIGROSO",DATOS!$Y$9,"") -> #REF! | Z19: =IF('F002'!#REF!="PELIGROSO",DATOS!$Z$9,"") -> #REF! | AA19: =IF('F002'!#REF!="PELIGROSO",DATOS!$AA$9,"") -> #REF! | AB19: =IF('F002'!#REF!="PELIGROSO",DATOS!$AB$9,"") -> #REF! | AC19: =IF('F002'!#REF!="PELIGROSO",DATOS!$AC$9,"") -> #REF! | AD19: =IF('F002'!#REF!="PELIGROSO",DATOS!$AD$9,"") -> #REF! | AE19: =IF('F002'!#REF!="PELIGROSO",DATOS!$AE$9,"") -> #REF! | AF19: =IF('F002'!#REF!="NO PELIGROSO",DATOS!$AF$9,"") -> #REF! | AG19: =IF('F002'!#REF!="NO PELIGROSO",DATOS!$AG$9,"") -> #REF! | AH19: =IF('F002'!#REF!="NO PELIGROSO",DATOS!$AH$9,"") -> #REF! | AI19: =IF('F002'!#REF!="NO PELIGROSO",DATOS!$AI$9,"") -> #REF! | AJ19: =IF('F002'!#REF!="NO PELIGROSO",DATOS!$AJ$9,"") -> #REF! | AK19: =IF('F002'!#REF!="NO PELIGROSO",DATOS!$AK$9,"") -> #REF! | AL19: =IF('F002'!#REF!="NO PELIGROSO",DATOS!$AL$9,"") -> #REF! | AM19: =IF('F002'!#REF!="NO PELIGROSO",DATOS!$AM$9,"") -> #REF!
A20: F20 | B20: =IF('F002'!#REF!="PELIGROSO",DATOS!$B$9,"") -> #REF! | C20: =IF('F002'!#REF!="PELIGROSO",DATOS!$C$9,"") -> #REF! | D20: =IF('F002'!#REF!="PELIGROSO",DATOS!$D$9,"") -> #REF! | E20: =IF('F002'!#REF!="PELIGROSO",DATOS!$E$9,"") -> #REF! | F20: =IF('F002'!#REF!="PELIGROSO",DATOS!$F$9,"") -> #REF! | G20: =IF('F002'!#REF!="PELIGROSO",DATOS!$G$9,"") -> #REF! | H20: =IF('F002'!#REF!="PELIGROSO",DATOS!$H$9,"") -> #REF! | I20: =IF('F002'!#REF!="PELIGROSO",DATOS!$I$9,"") -> #REF! | J20: =IF('F002'!#REF!="PELIGROSO",DATOS!$J$9,"") -> #REF! | K20: =IF('F002'!#REF!="PELIGROSO",DATOS!$K$9,"") -> #REF! | L20: =IF('F002'!#REF!="PELIGROSO",DATOS!$L$9,"") -> #REF! | M20: =IF('F002'!#REF!="PELIGROSO",DATOS!$M$9,"") -> #REF! | N20: =IF('F002'!#REF!="PELIGROSO",DATOS!$N$9,"") -> #REF! | O20: =IF('F002'!#REF!="PELIGROSO",DATOS!$O$9,"") -> #REF! | P20: =IF('F002'!#REF!="PELIGROSO",DATOS!$P$9,"") -> #REF! | Q20: =IF('F002'!#REF!="PELIGROSO",DATOS!$Q$9,"") -> #REF! | R20: =IF('F002'!#REF!="PELIGROSO",DATOS!$R$9,"") -> #REF! | S20: =IF('F002'!#REF!="PELIGROSO",DATOS!$S$9,"") -> #REF! | T20: =IF('F002'!#REF!="PELIGROSO",DATOS!$T$9,"") -> #REF! | U20: =IF('F002'!#REF!="PELIGROSO",DATOS!$U$9,"") -> #REF! | V20: =IF('F002'!#REF!="PELIGROSO",DATOS!$V$9,"") -> #REF! | W20: =IF('F002'!#REF!="PELIGROSO",DATOS!$W$9,"") -> #REF! | X20: =IF('F002'!#REF!="PELIGROSO",DATOS!$X$9,"") -> #REF! | Y20: =IF('F002'!#REF!="PELIGROSO",DATOS!$Y$9,"") -> #REF! | Z20: =IF('F002'!#REF!="PELIGROSO",DATOS!$Z$9,"") -> #REF! | AA20: =IF('F002'!#REF!="PELIGROSO",DATOS!$AA$9,"") -> #REF! | AB20: =IF('F002'!#REF!="PELIGROSO",DATOS!$AB$9,"") -> #REF! | AC20: =IF('F002'!#REF!="PELIGROSO",DATOS!$AC$9,"") -> #REF! | AD20: =IF('F002'!#REF!="PELIGROSO",DATOS!$AD$9,"") -> #REF! | AE20: =IF('F002'!#REF!="PELIGROSO",DATOS!$AE$9,"") -> #REF! | AF20: =IF('F002'!#REF!="NO PELIGROSO",DATOS!$AF$9,"") -> #REF! | AG20: =IF('F002'!#REF!="NO PELIGROSO",DATOS!$AG$9,"") -> #REF! | AH20: =IF('F002'!#REF!="NO PELIGROSO",DATOS!$AH$9,"") -> #REF! | AI20: =IF('F002'!#REF!="NO PELIGROSO",DATOS!$AI$9,"") -> #REF! | AJ20: =IF('F002'!#REF!="NO PELIGROSO",DATOS!$AJ$9,"") -> #REF! | AK20: =IF('F002'!#REF!="NO PELIGROSO",DATOS!$AK$9,"") -> #REF! | AL20: =IF('F002'!#REF!="NO PELIGROSO",DATOS!$AL$9,"") -> #REF! | AM20: =IF('F002'!#REF!="NO PELIGROSO",DATOS!$AM$9,"") -> #REF!
A21: F21 | B21: =IF('F002'!#REF!="PELIGROSO",DATOS!$B$9,"") -> #REF! | C21: =IF('F002'!#REF!="PELIGROSO",DATOS!$C$9,"") -> #REF! | D21: =IF('F002'!#REF!="PELIGROSO",DATOS!$D$9,"") -> #REF! | E21: =IF('F002'!#REF!="PELIGROSO",DATOS!$E$9,"") -> #REF! | F21: =IF('F002'!#REF!="PELIGROSO",DATOS!$F$9,"") -> #REF! | G21: =IF('F002'!#REF!="PELIGROSO",DATOS!$G$9,"") -> #REF! | H21: =IF('F002'!#REF!="PELIGROSO",DATOS!$H$9,"") -> #REF! | I21: =IF('F002'!#REF!="PELIGROSO",DATOS!$I$9,"") -> #REF! | J21: =IF('F002'!#REF!="PELIGROSO",DATOS!$J$9,"") -> #REF! | K21: =IF('F002'!#REF!="PELIGROSO",DATOS!$K$9,"") -> #REF! | L21: =IF('F002'!#REF!="PELIGROSO",DATOS!$L$9,"") -> #REF! | M21: =IF('F002'!#REF!="PELIGROSO",DATOS!$M$9,"") -> #REF! | N21: =IF('F002'!#REF!="PELIGROSO",DATOS!$N$9,"") -> #REF! | O21: =IF('F002'!#REF!="PELIGROSO",DATOS!$O$9,"") -> #REF! | P21: =IF('F002'!#REF!="PELIGROSO",DATOS!$P$9,"") -> #REF! | Q21: =IF('F002'!#REF!="PELIGROSO",DATOS!$Q$9,"") -> #REF! | R21: =IF('F002'!#REF!="PELIGROSO",DATOS!$R$9,"") -> #REF! | S21: =IF('F002'!#REF!="PELIGROSO",DATOS!$S$9,"") -> #REF! | T21: =IF('F002'!#REF!="PELIGROSO",DATOS!$T$9,"") -> #REF! | U21: =IF('F002'!#REF!="PELIGROSO",DATOS!$U$9,"") -> #REF! | V21: =IF('F002'!#REF!="PELIGROSO",DATOS!$V$9,"") -> #REF! | W21: =IF('F002'!#REF!="PELIGROSO",DATOS!$W$9,"") -> #REF! | X21: =IF('F002'!#REF!="PELIGROSO",DATOS!$X$9,"") -> #REF! | Y21: =IF('F002'!#REF!="PELIGROSO",DATOS!$Y$9,"") -> #REF! | Z21: =IF('F002'!#REF!="PELIGROSO",DATOS!$Z$9,"") -> #REF! | AA21: =IF('F002'!#REF!="PELIGROSO",DATOS!$AA$9,"") -> #REF! | AB21: =IF('F002'!#REF!="PELIGROSO",DATOS!$AB$9,"") -> #REF! | AC21: =IF('F002'!#REF!="PELIGROSO",DATOS!$AC$9,"") -> #REF! | AD21: =IF('F002'!#REF!="PELIGROSO",DATOS!$AD$9,"") -> #REF! | AE21: =IF('F002'!#REF!="PELIGROSO",DATOS!$AE$9,"") -> #REF! | AF21: =IF('F002'!#REF!="NO PELIGROSO",DATOS!$AF$9,"") -> #REF! | AG21: =IF('F002'!#REF!="NO PELIGROSO",DATOS!$AG$9,"") -> #REF! | AH21: =IF('F002'!#REF!="NO PELIGROSO",DATOS!$AH$9,"") -> #REF! | AI21: =IF('F002'!#REF!="NO PELIGROSO",DATOS!$AI$9,"") -> #REF! | AJ21: =IF('F002'!#REF!="NO PELIGROSO",DATOS!$AJ$9,"") -> #REF! | AK21: =IF('F002'!#REF!="NO PELIGROSO",DATOS!$AK$9,"") -> #REF! | AL21: =IF('F002'!#REF!="NO PELIGROSO",DATOS!$AL$9,"") -> #REF! | AM21: =IF('F002'!#REF!="NO PELIGROSO",DATOS!$AM$9,"") -> #REF!
... A26: F26 | B26: =IF('F002'!#REF!="PELIGROSO",DATOS!$B$9,"") -> #REF! | C26: =IF('F002'!#REF!="PELIGROSO",DATOS!$C$9,"") -> #REF! | D26: =IF('F002'!#REF!="PELIGROSO",DATOS!$D$9,"") -> #REF! | E26: =IF('F002'!#REF!="PELIGROSO",DATOS!$E$9,"") -> #REF! | F26: =IF('F002'!#REF!="PELIGROSO",DATOS!$F$9,"") -> #REF! | G26: =IF('F002'!#REF!="PELIGROSO",DATOS!$G$9,"") -> #REF! | H26: =IF('F002'!#REF!="PELIGROSO",DATOS!$H$9,"") -> #REF! | I26: =IF('F002'!#REF!="PELIGROSO",DATOS!$I$9,"") -> #REF! | J26: =IF('F002'!#REF!="PELIGROSO",DATOS!$J$9,"") -> #REF! | K26: =IF('F002'!#REF!="PELIGROSO",DATOS!$K$9,"") -> #REF! | L26: =IF('F002'!#REF!="PELIGROSO",DATOS!$L$9,"") -> #REF! | M26: =IF('F002'!#REF!="PELIGROSO",DATOS!$M$9,"") -> #REF! | N26: =IF('F002'!#REF!="PELIGROSO",DATOS!$N$9,"") -> #REF! | O26: =IF('F002'!#REF!="PELIGROSO",DATOS!$O$9,"") -> #REF! | P26: =IF('F002'!#REF!="PELIGROSO",DATOS!$P$9,"") -> #REF! | Q26: =IF('F002'!#REF!="PELIGROSO",DATOS!$Q$9,"") -> #REF! | R26: =IF('F002'!#REF!="PELIGROSO",DATOS!$R$9,"") -> #REF! | S26: =IF('F002'!#REF!="PELIGROSO",DATOS!$S$9,"") -> #REF! | T26: =IF('F002'!#REF!="PELIGROSO",DATOS!$T$9,"") -> #REF! | U26: =IF('F002'!#REF!="PELIGROSO",DATOS!$U$9,"") -> #REF! | V26: =IF('F002'!#REF!="PELIGROSO",DATOS!$V$9,"") -> #REF! | W26: =IF('F002'!#REF!="PELIGROSO",DATOS!$W$9,"") -> #REF! | X26: =IF('F002'!#REF!="PELIGROSO",DATOS!$X$9,"") -> #REF! | Y26: =IF('F002'!#REF!="PELIGROSO",DATOS!$Y$9,"") -> #REF! | Z26: =IF('F002'!#REF!="PELIGROSO",DATOS!$Z$9,"") -> #REF! | AA26: =IF('F002'!#REF!="PELIGROSO",DATOS!$AA$9,"") -> #REF! | AB26: =IF('F002'!#REF!="PELIGROSO",DATOS!$AB$9,"") -> #REF! | AC26: =IF('F002'!#REF!="PELIGROSO",DATOS!$AC$9,"") -> #REF! | AD26: =IF('F002'!#REF!="PELIGROSO",DATOS!$AD$9,"") -> #REF! | AE26: =IF('F002'!#REF!="PELIGROSO",DATOS!$AE$9,"") -> #REF! | AF26: =IF('F002'!#REF!="NO PELIGROSO",DATOS!$AF$9,"") -> #REF! | AG26: =IF('F002'!#REF!="NO PELIGROSO",DATOS!$AG$9,"") -> #REF! | AH26: =IF('F002'!#REF!="NO PELIGROSO",DATOS!$AH$9,"") -> #REF! | AI26: =IF('F002'!#REF!="NO PELIGROSO",DATOS!$AI$9,"") -> #REF! | AJ26: =IF('F002'!#REF!="NO PELIGROSO",DATOS!$AJ$9,"") -> #REF! | AK26: =IF('F002'!#REF!="NO PELIGROSO",DATOS!$AK$9,"") -> #REF! | AL26: =IF('F002'!#REF!="NO PELIGROSO",DATOS!$AL$9,"") -> #REF! | AM26: =IF('F002'!#REF!="NO PELIGROSO",DATOS!$AM$9,"") -> #REF!
A107: F107 | B107: =IF('F002'!$G10="PELIGROSO",DATOS!$B$9,"") | C107: =IF('F002'!$G10="PELIGROSO",DATOS!$C$9,"") | D107: =IF('F002'!$G10="PELIGROSO",DATOS!$D$9,"") | E107: =IF('F002'!$G10="PELIGROSO",DATOS!$E$9,"") | F107: =IF('F002'!$G10="PELIGROSO",DATOS!$F$9,"") | G107: =IF('F002'!$G10="PELIGROSO",DATOS!$G$9,"") | H107: =IF('F002'!$G10="PELIGROSO",DATOS!$H$9,"") | I107: =IF('F002'!$G10="PELIGROSO",DATOS!$I$9,"") | J107: =IF('F002'!$G10="PELIGROSO",DATOS!$J$9,"") | K107: =IF('F002'!$G10="PELIGROSO",DATOS!$K$9,"") | L107: =IF('F002'!$G10="PELIGROSO",DATOS!$L$9,"") | M107: =IF('F002'!$G10="PELIGROSO",DATOS!$M$9,"") | N107: =IF('F002'!$G10="PELIGROSO",DATOS!$N$9,"") | O107: =IF('F002'!$G10="PELIGROSO",DATOS!$O$9,"") | P107: =IF('F002'!$G10="PELIGROSO",DATOS!$P$9,"") | Q107: =IF('F002'!$G10="PELIGROSO",DATOS!$Q$9,"") | R107: =IF('F002'!$G10="PELIGROSO",DATOS!$R$9,"") | S107: =IF('F002'!$G10="PELIGROSO",DATOS!$S$9,"") | T107: =IF('F002'!$G10="PELIGROSO",DATOS!$T$9,"") | U107: =IF('F002'!$G10="PELIGROSO",DATOS!$U$9,"") | V107: =IF('F002'!$G10="PELIGROSO",DATOS!$V$9,"") | W107: =IF('F002'!$G10="PELIGROSO",DATOS!$W$9,"") | X107: =IF('F002'!$G10="PELIGROSO",DATOS!$X$9,"") | Y107: =IF('F002'!$G10="PELIGROSO",DATOS!$Y$9,"") | Z107: =IF('F002'!$G10="PELIGROSO",DATOS!$Z$9,"") | AA107: =IF('F002'!$G10="PELIGROSO",DATOS!$AA$9,"") | AB107: =IF('F002'!$G10="PELIGROSO",DATOS!$AB$9,"") | AC107: =IF('F002'!$G10="PELIGROSO",DATOS!$AC$9,"") | AD107: =IF('F002'!$G10="PELIGROSO",DATOS!$AD$9,"") | AE107: =IF('F002'!$G10="PELIGROSO",DATOS!$AE$9,"") | AF107: =IF('F002'!$G10="NO PELIGROSO",DATOS!$AF$9,"") | AG107: =IF('F002'!$G10="NO PELIGROSO",DATOS!$AG$9,"") | AH107: =IF('F002'!$G10="NO PELIGROSO",DATOS!$AH$9,"") | AI107: =IF('F002'!$G10="NO PELIGROSO",DATOS!$AI$9,"") | AJ107: =IF('F002'!$G10="NO PELIGROSO",DATOS!$AJ$9,"") | AK107: =IF('F002'!$G10="NO PELIGROSO",DATOS!$AK$9,"") | AL107: =IF('F002'!$G10="NO PELIGROSO",DATOS!$AL$9,"") | AM107: =IF('F002'!$G10="NO PELIGROSO",DATOS!$AM$9,"")
A108: F108 | B108: =IF('F002'!$G11="PELIGROSO",DATOS!$B$9,"") | C108: =IF('F002'!$G11="PELIGROSO",DATOS!$C$9,"") | D108: =IF('F002'!$G11="PELIGROSO",DATOS!$D$9,"") | E108: =IF('F002'!$G11="PELIGROSO",DATOS!$E$9,"") | F108: =IF('F002'!$G11="PELIGROSO",DATOS!$F$9,"") | G108: =IF('F002'!$G11="PELIGROSO",DATOS!$G$9,"") | H108: =IF('F002'!$G11="PELIGROSO",DATOS!$H$9,"") | I108: =IF('F002'!$G11="PELIGROSO",DATOS!$I$9,"") | J108: =IF('F002'!$G11="PELIGROSO",DATOS!$J$9,"") | K108: =IF('F002'!$G11="PELIGROSO",DATOS!$K$9,"") | L108: =IF('F002'!$G11="PELIGROSO",DATOS!$L$9,"") | M108: =IF('F002'!$G11="PELIGROSO",DATOS!$M$9,"") | N108: =IF('F002'!$G11="PELIGROSO",DATOS!$N$9,"") | O108: =IF('F002'!$G11="PELIGROSO",DATOS!$O$9,"") | P108: =IF('F002'!$G11="PELIGROSO",DATOS!$P$9,"") | Q108: =IF('F002'!$G11="PELIGROSO",DATOS!$Q$9,"") | R108: =IF('F002'!$G11="PELIGROSO",DATOS!$R$9,"") | S108: =IF('F002'!$G11="PELIGROSO",DATOS!$S$9,"") | T108: =IF('F002'!$G11="PELIGROSO",DATOS!$T$9,"") | U108: =IF('F002'!$G11="PELIGROSO",DATOS!$U$9,"") | V108: =IF('F002'!$G11="PELIGROSO",DATOS!$V$9,"") | W108: =IF('F002'!$G11="PELIGROSO",DATOS!$W$9,"") | X108: =IF('F002'!$G11="PELIGROSO",DATOS!$X$9,"") | Y108: =IF('F002'!$G11="PELIGROSO",DATOS!$Y$9,"") | Z108: =IF('F002'!$G11="PELIGROSO",DATOS!$Z$9,"") | AA108: =IF('F002'!$G11="PELIGROSO",DATOS!$AA$9,"") | AB108: =IF('F002'!$G11="PELIGROSO",DATOS!$AB$9,"") | AC108: =IF('F002'!$G11="PELIGROSO",DATOS!$AC$9,"") | AD108: =IF('F002'!$G11="PELIGROSO",DATOS!$AD$9,"") | AE108: =IF('F002'!$G11="PELIGROSO",DATOS!$AE$9,"") | AF108: =IF('F002'!$G11="NO PELIGROSO",DATOS!$AF$9,"") | AG108: =IF('F002'!$G11="NO PELIGROSO",DATOS!$AG$9,"") | AH108: =IF('F002'!$G11="NO PELIGROSO",DATOS!$AH$9,"") | AI108: =IF('F002'!$G11="NO PELIGROSO",DATOS!$AI$9,"") | AJ108: =IF('F002'!$G11="NO PELIGROSO",DATOS!$AJ$9,"") | AK108: =IF('F002'!$G11="NO PELIGROSO",DATOS!$AK$9,"") | AL108: =IF('F002'!$G11="NO PELIGROSO",DATOS!$AL$9,"") | AM108: =IF('F002'!$G11="NO PELIGROSO",DATOS!$AM$9,"")
A109: F109 | B109: =IF('F002'!$G12="PELIGROSO",DATOS!$B$9,"") | C109: =IF('F002'!$G12="PELIGROSO",DATOS!$C$9,"") | D109: =IF('F002'!$G12="PELIGROSO",DATOS!$D$9,"") | E109: =IF('F002'!$G12="PELIGROSO",DATOS!$E$9,"") | F109: =IF('F002'!$G12="PELIGROSO",DATOS!$F$9,"") | G109: =IF('F002'!$G12="PELIGROSO",DATOS!$G$9,"") | H109: =IF('F002'!$G12="PELIGROSO",DATOS!$H$9,"") | I109: =IF('F002'!$G12="PELIGROSO",DATOS!$I$9,"") | J109: =IF('F002'!$G12="PELIGROSO",DATOS!$J$9,"") | K109: =IF('F002'!$G12="PELIGROSO",DATOS!$K$9,"") | L109: =IF('F002'!$G12="PELIGROSO",DATOS!$L$9,"") | M109: =IF('F002'!$G12="PELIGROSO",DATOS!$M$9,"") | N109: =IF('F002'!$G12="PELIGROSO",DATOS!$N$9,"") | O109: =IF('F002'!$G12="PELIGROSO",DATOS!$O$9,"") | P109: =IF('F002'!$G12="PELIGROSO",DATOS!$P$9,"") | Q109: =IF('F002'!$G12="PELIGROSO",DATOS!$Q$9,"") | R109: =IF('F002'!$G12="PELIGROSO",DATOS!$R$9,"") | S109: =IF('F002'!$G12="PELIGROSO",DATOS!$S$9,"") | T109: =IF('F002'!$G12="PELIGROSO",DATOS!$T$9,"") | U109: =IF('F002'!$G12="PELIGROSO",DATOS!$U$9,"") | V109: =IF('F002'!$G12="PELIGROSO",DATOS!$V$9,"") | W109: =IF('F002'!$G12="PELIGROSO",DATOS!$W$9,"") | X109: =IF('F002'!$G12="PELIGROSO",DATOS!$X$9,"") | Y109: =IF('F002'!$G12="PELIGROSO",DATOS!$Y$9,"") | Z109: =IF('F002'!$G12="PELIGROSO",DATOS!$Z$9,"") | AA109: =IF('F002'!$G12="PELIGROSO",DATOS!$AA$9,"") | AB109: =IF('F002'!$G12="PELIGROSO",DATOS!$AB$9,"") | AC109: =IF('F002'!$G12="PELIGROSO",DATOS!$AC$9,"") | AD109: =IF('F002'!$G12="PELIGROSO",DATOS!$AD$9,"") | AE109: =IF('F002'!$G12="PELIGROSO",DATOS!$AE$9,"") | AF109: =IF('F002'!$G12="NO PELIGROSO",DATOS!$AF$9,"") | AG109: =IF('F002'!$G12="NO PELIGROSO",DATOS!$AG$9,"") | AH109: =IF('F002'!$G12="NO PELIGROSO",DATOS!$AH$9,"") | AI109: =IF('F002'!$G12="NO PELIGROSO",DATOS!$AI$9,"") | AJ109: =IF('F002'!$G12="NO PELIGROSO",DATOS!$AJ$9,"") | AK109: =IF('F002'!$G12="NO PELIGROSO",DATOS!$AK$9,"") | AL109: =IF('F002'!$G12="NO PELIGROSO",DATOS!$AL$9,"") | AM109: =IF('F002'!$G12="NO PELIGROSO",DATOS!$AM$9,"")
A110: F110 | B110: =IF('F002'!$G13="PELIGROSO",DATOS!$B$9,"") | C110: =IF('F002'!$G13="PELIGROSO",DATOS!$C$9,"") | D110: =IF('F002'!$G13="PELIGROSO",DATOS!$D$9,"") | E110: =IF('F002'!$G13="PELIGROSO",DATOS!$E$9,"") | F110: =IF('F002'!$G13="PELIGROSO",DATOS!$F$9,"") | G110: =IF('F002'!$G13="PELIGROSO",DATOS!$G$9,"") | H110: =IF('F002'!$G13="PELIGROSO",DATOS!$H$9,"") | I110: =IF('F002'!$G13="PELIGROSO",DATOS!$I$9,"") | J110: =IF('F002'!$G13="PELIGROSO",DATOS!$J$9,"") | K110: =IF('F002'!$G13="PELIGROSO",DATOS!$K$9,"") | L110: =IF('F002'!$G13="PELIGROSO",DATOS!$L$9,"") | M110: =IF('F002'!$G13="PELIGROSO",DATOS!$M$9,"") | N110: =IF('F002'!$G13="PELIGROSO",DATOS!$N$9,"") | O110: =IF('F002'!$G13="PELIGROSO",DATOS!$O$9,"") | P110: =IF('F002'!$G13="PELIGROSO",DATOS!$P$9,"") | Q110: =IF('F002'!$G13="PELIGROSO",DATOS!$Q$9,"") | R110: =IF('F002'!$G13="PELIGROSO",DATOS!$R$9,"") | S110: =IF('F002'!$G13="PELIGROSO",DATOS!$S$9,"") | T110: =IF('F002'!$G13="PELIGROSO",DATOS!$T$9,"") | U110: =IF('F002'!$G13="PELIGROSO",DATOS!$U$9,"") | V110: =IF('F002'!$G13="PELIGROSO",DATOS!$V$9,"") | W110: =IF('F002'!$G13="PELIGROSO",DATOS!$W$9,"") | X110: =IF('F002'!$G13="PELIGROSO",DATOS!$X$9,"") | Y110: =IF('F002'!$G13="PELIGROSO",DATOS!$Y$9,"") | Z110: =IF('F002'!$G13="PELIGROSO",DATOS!$Z$9,"") | AA110: =IF('F002'!$G13="PELIGROSO",DATOS!$AA$9,"") | AB110: =IF('F002'!$G13="PELIGROSO",DATOS!$AB$9,"") | AC110: =IF('F002'!$G13="PELIGROSO",DATOS!$AC$9,"") | AD110: =IF('F002'!$G13="PELIGROSO",DATOS!$AD$9,"") | AE110: =IF('F002'!$G13="PELIGROSO",DATOS!$AE$9,"") | AF110: =IF('F002'!$G13="NO PELIGROSO",DATOS!$AF$9,"") | AG110: =IF('F002'!$G13="NO PELIGROSO",DATOS!$AG$9,"") | AH110: =IF('F002'!$G13="NO PELIGROSO",DATOS!$AH$9,"") | AI110: =IF('F002'!$G13="NO PELIGROSO",DATOS!$AI$9,"") | AJ110: =IF('F002'!$G13="NO PELIGROSO",DATOS!$AJ$9,"") | AK110: =IF('F002'!$G13="NO PELIGROSO",DATOS!$AK$9,"") | AL110: =IF('F002'!$G13="NO PELIGROSO",DATOS!$AL$9,"") | AM110: =IF('F002'!$G13="NO PELIGROSO",DATOS!$AM$9,"")
A111: F111 | B111: =IF('F002'!$G14="PELIGROSO",DATOS!$B$9,"") | C111: =IF('F002'!$G14="PELIGROSO",DATOS!$C$9,"") | D111: =IF('F002'!$G14="PELIGROSO",DATOS!$D$9,"") | E111: =IF('F002'!$G14="PELIGROSO",DATOS!$E$9,"") | F111: =IF('F002'!$G14="PELIGROSO",DATOS!$F$9,"") | G111: =IF('F002'!$G14="PELIGROSO",DATOS!$G$9,"") | H111: =IF('F002'!$G14="PELIGROSO",DATOS!$H$9,"") | I111: =IF('F002'!$G14="PELIGROSO",DATOS!$I$9,"") | J111: =IF('F002'!$G14="PELIGROSO",DATOS!$J$9,"") | K111: =IF('F002'!$G14="PELIGROSO",DATOS!$K$9,"") | L111: =IF('F002'!$G14="PELIGROSO",DATOS!$L$9,"") | M111: =IF('F002'!$G14="PELIGROSO",DATOS!$M$9,"") | N111: =IF('F002'!$G14="PELIGROSO",DATOS!$N$9,"") | O111: =IF('F002'!$G14="PELIGROSO",DATOS!$O$9,"") | P111: =IF('F002'!$G14="PELIGROSO",DATOS!$P$9,"") | Q111: =IF('F002'!$G14="PELIGROSO",DATOS!$Q$9,"") | R111: =IF('F002'!$G14="PELIGROSO",DATOS!$R$9,"") | S111: =IF('F002'!$G14="PELIGROSO",DATOS!$S$9,"") | T111: =IF('F002'!$G14="PELIGROSO",DATOS!$T$9,"") | U111: =IF('F002'!$G14="PELIGROSO",DATOS!$U$9,"") | V111: =IF('F002'!$G14="PELIGROSO",DATOS!$V$9,"") | W111: =IF('F002'!$G14="PELIGROSO",DATOS!$W$9,"") | X111: =IF('F002'!$G14="PELIGROSO",DATOS!$X$9,"") | Y111: =IF('F002'!$G14="PELIGROSO",DATOS!$Y$9,"") | Z111: =IF('F002'!$G14="PELIGROSO",DATOS!$Z$9,"") | AA111: =IF('F002'!$G14="PELIGROSO",DATOS!$AA$9,"") | AB111: =IF('F002'!$G14="PELIGROSO",DATOS!$AB$9,"") | AC111: =IF('F002'!$G14="PELIGROSO",DATOS!$AC$9,"") | AD111: =IF('F002'!$G14="PELIGROSO",DATOS!$AD$9,"") | AE111: =IF('F002'!$G14="PELIGROSO",DATOS!$AE$9,"") | AF111: =IF('F002'!$G14="NO PELIGROSO",DATOS!$AF$9,"") | AG111: =IF('F002'!$G14="NO PELIGROSO",DATOS!$AG$9,"") | AH111: =IF('F002'!$G14="NO PELIGROSO",DATOS!$AH$9,"") | AI111: =IF('F002'!$G14="NO PELIGROSO",DATOS!$AI$9,"") | AJ111: =IF('F002'!$G14="NO PELIGROSO",DATOS!$AJ$9,"") | AK111: =IF('F002'!$G14="NO PELIGROSO",DATOS!$AK$9,"") | AL111: =IF('F002'!$G14="NO PELIGROSO",DATOS!$AL$9,"") | AM111: =IF('F002'!$G14="NO PELIGROSO",DATOS!$AM$9,"")
A112: F112 | B112: =IF('F002'!$G15="PELIGROSO",DATOS!$B$9,"") | C112: =IF('F002'!$G15="PELIGROSO",DATOS!$C$9,"") | D112: =IF('F002'!$G15="PELIGROSO",DATOS!$D$9,"") | E112: =IF('F002'!$G15="PELIGROSO",DATOS!$E$9,"") | F112: =IF('F002'!$G15="PELIGROSO",DATOS!$F$9,"") | G112: =IF('F002'!$G15="PELIGROSO",DATOS!$G$9,"") | H112: =IF('F002'!$G15="PELIGROSO",DATOS!$H$9,"") | I112: =IF('F002'!$G15="PELIGROSO",DATOS!$I$9,"") | J112: =IF('F002'!$G15="PELIGROSO",DATOS!$J$9,"") | K112: =IF('F002'!$G15="PELIGROSO",DATOS!$K$9,"") | L112: =IF('F002'!$G15="PELIGROSO",DATOS!$L$9,"") | M112: =IF('F002'!$G15="PELIGROSO",DATOS!$M$9,"") | N112: =IF('F002'!$G15="PELIGROSO",DATOS!$N$9,"") | O112: =IF('F002'!$G15="PELIGROSO",DATOS!$O$9,"") | P112: =IF('F002'!$G15="PELIGROSO",DATOS!$P$9,"") | Q112: =IF('F002'!$G15="PELIGROSO",DATOS!$Q$9,"") | R112: =IF('F002'!$G15="PELIGROSO",DATOS!$R$9,"") | S112: =IF('F002'!$G15="PELIGROSO",DATOS!$S$9,"") | T112: =IF('F002'!$G15="PELIGROSO",DATOS!$T$9,"") | U112: =IF('F002'!$G15="PELIGROSO",DATOS!$U$9,"") | V112: =IF('F002'!$G15="PELIGROSO",DATOS!$V$9,"") | W112: =IF('F002'!$G15="PELIGROSO",DATOS!$W$9,"") | X112: =IF('F002'!$G15="PELIGROSO",DATOS!$X$9,"") | Y112: =IF('F002'!$G15="PELIGROSO",DATOS!$Y$9,"") | Z112: =IF('F002'!$G15="PELIGROSO",DATOS!$Z$9,"") | AA112: =IF('F002'!$G15="PELIGROSO",DATOS!$AA$9,"") | AB112: =IF('F002'!$G15="PELIGROSO",DATOS!$AB$9,"") | AC112: =IF('F002'!$G15="PELIGROSO",DATOS!$AC$9,"") | AD112: =IF('F002'!$G15="PELIGROSO",DATOS!$AD$9,"") | AE112: =IF('F002'!$G15="PELIGROSO",DATOS!$AE$9,"") | AF112: =IF('F002'!$G15="NO PELIGROSO",DATOS!$AF$9,"") | AG112: =IF('F002'!$G15="NO PELIGROSO",DATOS!$AG$9,"") | AH112: =IF('F002'!$G15="NO PELIGROSO",DATOS!$AH$9,"") | AI112: =IF('F002'!$G15="NO PELIGROSO",DATOS!$AI$9,"") | AJ112: =IF('F002'!$G15="NO PELIGROSO",DATOS!$AJ$9,"") | AK112: =IF('F002'!$G15="NO PELIGROSO",DATOS!$AK$9,"") | AL112: =IF('F002'!$G15="NO PELIGROSO",DATOS!$AL$9,"") | AM112: =IF('F002'!$G15="NO PELIGROSO",DATOS!$AM$9,"")
A113: F113 | B113: =IF('F002'!$G16="PELIGROSO",DATOS!$B$9,"") | C113: =IF('F002'!$G16="PELIGROSO",DATOS!$C$9,"") | D113: =IF('F002'!$G16="PELIGROSO",DATOS!$D$9,"") | E113: =IF('F002'!$G16="PELIGROSO",DATOS!$E$9,"") | F113: =IF('F002'!$G16="PELIGROSO",DATOS!$F$9,"") | G113: =IF('F002'!$G16="PELIGROSO",DATOS!$G$9,"") | H113: =IF('F002'!$G16="PELIGROSO",DATOS!$H$9,"") | I113: =IF('F002'!$G16="PELIGROSO",DATOS!$I$9,"") | J113: =IF('F002'!$G16="PELIGROSO",DATOS!$J$9,"") | K113: =IF('F002'!$G16="PELIGROSO",DATOS!$K$9,"") | L113: =IF('F002'!$G16="PELIGROSO",DATOS!$L$9,"") | M113: =IF('F002'!$G16="PELIGROSO",DATOS!$M$9,"") | N113: =IF('F002'!$G16="PELIGROSO",DATOS!$N$9,"") | O113: =IF('F002'!$G16="PELIGROSO",DATOS!$O$9,"") | P113: =IF('F002'!$G16="PELIGROSO",DATOS!$P$9,"") | Q113: =IF('F002'!$G16="PELIGROSO",DATOS!$Q$9,"") | R113: =IF('F002'!$G16="PELIGROSO",DATOS!$R$9,"") | S113: =IF('F002'!$G16="PELIGROSO",DATOS!$S$9,"") | T113: =IF('F002'!$G16="PELIGROSO",DATOS!$T$9,"") | U113: =IF('F002'!$G16="PELIGROSO",DATOS!$U$9,"") | V113: =IF('F002'!$G16="PELIGROSO",DATOS!$V$9,"") | W113: =IF('F002'!$G16="PELIGROSO",DATOS!$W$9,"") | X113: =IF('F002'!$G16="PELIGROSO",DATOS!$X$9,"") | Y113: =IF('F002'!$G16="PELIGROSO",DATOS!$Y$9,"") | Z113: =IF('F002'!$G16="PELIGROSO",DATOS!$Z$9,"") | AA113: =IF('F002'!$G16="PELIGROSO",DATOS!$AA$9,"") | AB113: =IF('F002'!$G16="PELIGROSO",DATOS!$AB$9,"") | AC113: =IF('F002'!$G16="PELIGROSO",DATOS!$AC$9,"") | AD113: =IF('F002'!$G16="PELIGROSO",DATOS!$AD$9,"") | AE113: =IF('F002'!$G16="PELIGROSO",DATOS!$AE$9,"") | AF113: =IF('F002'!$G16="NO PELIGROSO",DATOS!$AF$9,"") | AG113: =IF('F002'!$G16="NO PELIGROSO",DATOS!$AG$9,"") | AH113: =IF('F002'!$G16="NO PELIGROSO",DATOS!$AH$9,"") | AI113: =IF('F002'!$G16="NO PELIGROSO",DATOS!$AI$9,"") | AJ113: =IF('F002'!$G16="NO PELIGROSO",DATOS!$AJ$9,"") | AK113: =IF('F002'!$G16="NO PELIGROSO",DATOS!$AK$9,"") | AL113: =IF('F002'!$G16="NO PELIGROSO",DATOS!$AL$9,"") | AM113: =IF('F002'!$G16="NO PELIGROSO",DATOS!$AM$9,"")
A114: F114 | B114: =IF('F002'!$G17="PELIGROSO",DATOS!$B$9,"") | C114: =IF('F002'!$G17="PELIGROSO",DATOS!$C$9,"") | D114: =IF('F002'!$G17="PELIGROSO",DATOS!$D$9,"") | E114: =IF('F002'!$G17="PELIGROSO",DATOS!$E$9,"") | F114: =IF('F002'!$G17="PELIGROSO",DATOS!$F$9,"") | G114: =IF('F002'!$G17="PELIGROSO",DATOS!$G$9,"") | H114: =IF('F002'!$G17="PELIGROSO",DATOS!$H$9,"") | I114: =IF('F002'!$G17="PELIGROSO",DATOS!$I$9,"") | J114: =IF('F002'!$G17="PELIGROSO",DATOS!$J$9,"") | K114: =IF('F002'!$G17="PELIGROSO",DATOS!$K$9,"") | L114: =IF('F002'!$G17="PELIGROSO",DATOS!$L$9,"") | M114: =IF('F002'!$G17="PELIGROSO",DATOS!$M$9,"") | N114: =IF('F002'!$G17="PELIGROSO",DATOS!$N$9,"") | O114: =IF('F002'!$G17="PELIGROSO",DATOS!$O$9,"") | P114: =IF('F002'!$G17="PELIGROSO",DATOS!$P$9,"") | Q114: =IF('F002'!$G17="PELIGROSO",DATOS!$Q$9,"") | R114: =IF('F002'!$G17="PELIGROSO",DATOS!$R$9,"") | S114: =IF('F002'!$G17="PELIGROSO",DATOS!$S$9,"") | T114: =IF('F002'!$G17="PELIGROSO",DATOS!$T$9,"") | U114: =IF('F002'!$G17="PELIGROSO",DATOS!$U$9,"") | V114: =IF('F002'!$G17="PELIGROSO",DATOS!$V$9,"") | W114: =IF('F002'!$G17="PELIGROSO",DATOS!$W$9,"") | X114: =IF('F002'!$G17="PELIGROSO",DATOS!$X$9,"") | Y114: =IF('F002'!$G17="PELIGROSO",DATOS!$Y$9,"") | Z114: =IF('F002'!$G17="PELIGROSO",DATOS!$Z$9,"") | AA114: =IF('F002'!$G17="PELIGROSO",DATOS!$AA$9,"") | AB114: =IF('F002'!$G17="PELIGROSO",DATOS!$AB$9,"") | AC114: =IF('F002'!$G17="PELIGROSO",DATOS!$AC$9,"") | AD114: =IF('F002'!$G17="PELIGROSO",DATOS!$AD$9,"") | AE114: =IF('F002'!$G17="PELIGROSO",DATOS!$AE$9,"") | AF114: =IF('F002'!$G17="NO PELIGROSO",DATOS!$AF$9,"") | AG114: =IF('F002'!$G17="NO PELIGROSO",DATOS!$AG$9,"") | AH114: =IF('F002'!$G17="NO PELIGROSO",DATOS!$AH$9,"") | AI114: =IF('F002'!$G17="NO PELIGROSO",DATOS!$AI$9,"") | AJ114: =IF('F002'!$G17="NO PELIGROSO",DATOS!$AJ$9,"") | AK114: =IF('F002'!$G17="NO PELIGROSO",DATOS!$AK$9,"") | AL114: =IF('F002'!$G17="NO PELIGROSO",DATOS!$AL$9,"") | AM114: =IF('F002'!$G17="NO PELIGROSO",DATOS!$AM$9,"")
A115: F115 | B115: =IF('F002'!$G18="PELIGROSO",DATOS!$B$9,"") | C115: =IF('F002'!$G18="PELIGROSO",DATOS!$C$9,"") | D115: =IF('F002'!$G18="PELIGROSO",DATOS!$D$9,"") | E115: =IF('F002'!$G18="PELIGROSO",DATOS!$E$9,"") | F115: =IF('F002'!$G18="PELIGROSO",DATOS!$F$9,"") | G115: =IF('F002'!$G18="PELIGROSO",DATOS!$G$9,"") | H115: =IF('F002'!$G18="PELIGROSO",DATOS!$H$9,"") | I115: =IF('F002'!$G18="PELIGROSO",DATOS!$I$9,"") | J115: =IF('F002'!$G18="PELIGROSO",DATOS!$J$9,"") | K115: =IF('F002'!$G18="PELIGROSO",DATOS!$K$9,"") | L115: =IF('F002'!$G18="PELIGROSO",DATOS!$L$9,"") | M115: =IF('F002'!$G18="PELIGROSO",DATOS!$M$9,"") | N115: =IF('F002'!$G18="PELIGROSO",DATOS!$N$9,"") | O115: =IF('F002'!$G18="PELIGROSO",DATOS!$O$9,"") | P115: =IF('F002'!$G18="PELIGROSO",DATOS!$P$9,"") | Q115: =IF('F002'!$G18="PELIGROSO",DATOS!$Q$9,"") | R115: =IF('F002'!$G18="PELIGROSO",DATOS!$R$9,"") | S115: =IF('F002'!$G18="PELIGROSO",DATOS!$S$9,"") | T115: =IF('F002'!$G18="PELIGROSO",DATOS!$T$9,"") | U115: =IF('F002'!$G18="PELIGROSO",DATOS!$U$9,"") | V115: =IF('F002'!$G18="PELIGROSO",DATOS!$V$9,"") | W115: =IF('F002'!$G18="PELIGROSO",DATOS!$W$9,"") | X115: =IF('F002'!$G18="PELIGROSO",DATOS!$X$9,"") | Y115: =IF('F002'!$G18="PELIGROSO",DATOS!$Y$9,"") | Z115: =IF('F002'!$G18="PELIGROSO",DATOS!$Z$9,"") | AA115: =IF('F002'!$G18="PELIGROSO",DATOS!$AA$9,"") | AB115: =IF('F002'!$G18="PELIGROSO",DATOS!$AB$9,"") | AC115: =IF('F002'!$G18="PELIGROSO",DATOS!$AC$9,"") | AD115: =IF('F002'!$G18="PELIGROSO",DATOS!$AD$9,"") | AE115: =IF('F002'!$G18="PELIGROSO",DATOS!$AE$9,"") | AF115: =IF('F002'!$G18="NO PELIGROSO",DATOS!$AF$9,"") | AG115: =IF('F002'!$G18="NO PELIGROSO",DATOS!$AG$9,"") | AH115: =IF('F002'!$G18="NO PELIGROSO",DATOS!$AH$9,"") | AI115: =IF('F002'!$G18="NO PELIGROSO",DATOS!$AI$9,"") | AJ115: =IF('F002'!$G18="NO PELIGROSO",DATOS!$AJ$9,"") | AK115: =IF('F002'!$G18="NO PELIGROSO",DATOS!$AK$9,"") | AL115: =IF('F002'!$G18="NO PELIGROSO",DATOS!$AL$9,"") | AM115: =IF('F002'!$G18="NO PELIGROSO",DATOS!$AM$9,"")
A116: F116 | AF116: =IF('F002'!$G19="NO PELIGROSO",DATOS!$AF$9,"") | AG116: =IF('F002'!$G19="NO PELIGROSO",DATOS!$AG$9,"") | AH116: =IF('F002'!$G19="NO PELIGROSO",DATOS!$AH$9,"") | AI116: =IF('F002'!$G19="NO PELIGROSO",DATOS!$AI$9,"") | AJ116: =IF('F002'!$G19="NO PELIGROSO",DATOS!$AJ$9,"") | AK116: =IF('F002'!$G19="NO PELIGROSO",DATOS!$AK$9,"") | AL116: =IF('F002'!$G19="NO PELIGROSO",DATOS!$AL$9,"") | AM116: =IF('F002'!$G19="NO PELIGROSO",DATOS!$AM$9,"")
A117: F117 | AF117: =IF('F002'!$G20="NO PELIGROSO",DATOS!$AF$9,"") | AG117: =IF('F002'!$G20="NO PELIGROSO",DATOS!$AG$9,"") | AH117: =IF('F002'!$G20="NO PELIGROSO",DATOS!$AH$9,"") | AI117: =IF('F002'!$G20="NO PELIGROSO",DATOS!$AI$9,"") | AJ117: =IF('F002'!$G20="NO PELIGROSO",DATOS!$AJ$9,"") | AK117: =IF('F002'!$G20="NO PELIGROSO",DATOS!$AK$9,"") | AL117: =IF('F002'!$G20="NO PELIGROSO",DATOS!$AL$9,"") | AM117: =IF('F002'!$G20="NO PELIGROSO",DATOS!$AM$9,"")
A118: F118 | AF118: =IF('F002'!$G21="NO PELIGROSO",DATOS!$AF$9,"") | AG118: =IF('F002'!$G21="NO PELIGROSO",DATOS!$AG$9,"") | AH118: =IF('F002'!$G21="NO PELIGROSO",DATOS!$AH$9,"") | AI118: =IF('F002'!$G21="NO PELIGROSO",DATOS!$AI$9,"") | AJ118: =IF('F002'!$G21="NO PELIGROSO",DATOS!$AJ$9,"") | AK118: =IF('F002'!$G21="NO PELIGROSO",DATOS!$AK$9,"") | AL118: =IF('F002'!$G21="NO PELIGROSO",DATOS!$AL$9,"") | AM118: =IF('F002'!$G21="NO PELIGROSO",DATOS!$AM$9,"")
A119: F119 | AF119: =IF('F002'!$G22="NO PELIGROSO",DATOS!$AF$9,"") | AG119: =IF('F002'!$G22="NO PELIGROSO",DATOS!$AG$9,"") | AH119: =IF('F002'!$G22="NO PELIGROSO",DATOS!$AH$9,"") | AI119: =IF('F002'!$G22="NO PELIGROSO",DATOS!$AI$9,"") | AJ119: =IF('F002'!$G22="NO PELIGROSO",DATOS!$AJ$9,"") | AK119: =IF('F002'!$G22="NO PELIGROSO",DATOS!$AK$9,"") | AL119: =IF('F002'!$G22="NO PELIGROSO",DATOS!$AL$9,"") | AM119: =IF('F002'!$G22="NO PELIGROSO",DATOS!$AM$9,"")
A120: F120 | AF120: =IF('F002'!$G23="NO PELIGROSO",DATOS!$AF$9,"") | AG120: =IF('F002'!$G23="NO PELIGROSO",DATOS!$AG$9,"") | AH120: =IF('F002'!$G23="NO PELIGROSO",DATOS!$AH$9,"") | AI120: =IF('F002'!$G23="NO PELIGROSO",DATOS!$AI$9,"") | AJ120: =IF('F002'!$G23="NO PELIGROSO",DATOS!$AJ$9,"") | AK120: =IF('F002'!$G23="NO PELIGROSO",DATOS!$AK$9,"") | AL120: =IF('F002'!$G23="NO PELIGROSO",DATOS!$AL$9,"") | AM120: =IF('F002'!$G23="NO PELIGROSO",DATOS!$AM$9,"")
A121: F121 | AF121: =IF('F002'!$G24="NO PELIGROSO",DATOS!$AF$9,"") | AG121: =IF('F002'!$G24="NO PELIGROSO",DATOS!$AG$9,"") | AH121: =IF('F002'!$G24="NO PELIGROSO",DATOS!$AH$9,"") | AI121: =IF('F002'!$G24="NO PELIGROSO",DATOS!$AI$9,"") | AJ121: =IF('F002'!$G24="NO PELIGROSO",DATOS!$AJ$9,"") | AK121: =IF('F002'!$G24="NO PELIGROSO",DATOS!$AK$9,"") | AL121: =IF('F002'!$G24="NO PELIGROSO",DATOS!$AL$9,"") | AM121: =IF('F002'!$G24="NO PELIGROSO",DATOS!$AM$9,"")
A122: F122 | AF122: =IF('F002'!$G25="NO PELIGROSO",DATOS!$AF$9,"") | AG122: =IF('F002'!$G25="NO PELIGROSO",DATOS!$AG$9,"") | AH122: =IF('F002'!$G25="NO PELIGROSO",DATOS!$AH$9,"") | AI122: =IF('F002'!$G25="NO PELIGROSO",DATOS!$AI$9,"") | AJ122: =IF('F002'!$G25="NO PELIGROSO",DATOS!$AJ$9,"") | AK122: =IF('F002'!$G25="NO PELIGROSO",DATOS!$AK$9,"") | AL122: =IF('F002'!$G25="NO PELIGROSO",DATOS!$AL$9,"") | AM122: =IF('F002'!$G25="NO PELIGROSO",DATOS!$AM$9,"")
A123: F123 | AF123: =IF('F002'!$G26="NO PELIGROSO",DATOS!$AF$9,"") | AG123: =IF('F002'!$G26="NO PELIGROSO",DATOS!$AG$9,"") | AH123: =IF('F002'!$G26="NO PELIGROSO",DATOS!$AH$9,"") | AI123: =IF('F002'!$G26="NO PELIGROSO",DATOS!$AI$9,"") | AJ123: =IF('F002'!$G26="NO PELIGROSO",DATOS!$AJ$9,"") | AK123: =IF('F002'!$G26="NO PELIGROSO",DATOS!$AK$9,"") | AL123: =IF('F002'!$G26="NO PELIGROSO",DATOS!$AL$9,"") | AM123: =IF('F002'!$G26="NO PELIGROSO",DATOS!$AM$9,"")
A124: F124 | AF124: =IF('F002'!$G27="NO PELIGROSO",DATOS!$AF$9,"") | AG124: =IF('F002'!$G27="NO PELIGROSO",DATOS!$AG$9,"") | AH124: =IF('F002'!$G27="NO PELIGROSO",DATOS!$AH$9,"") | AI124: =IF('F002'!$G27="NO PELIGROSO",DATOS!$AI$9,"") | AJ124: =IF('F002'!$G27="NO PELIGROSO",DATOS!$AJ$9,"") | AK124: =IF('F002'!$G27="NO PELIGROSO",DATOS!$AK$9,"") | AL124: =IF('F002'!$G27="NO PELIGROSO",DATOS!$AL$9,"") | AM124: =IF('F002'!$G27="NO PELIGROSO",DATOS!$AM$9,"")
A125: F125 | AF125: =IF('F002'!$G28="NO PELIGROSO",DATOS!$AF$9,"") | AG125: =IF('F002'!$G28="NO PELIGROSO",DATOS!$AG$9,"") | AH125: =IF('F002'!$G28="NO PELIGROSO",DATOS!$AH$9,"") | AI125: =IF('F002'!$G28="NO PELIGROSO",DATOS!$AI$9,"") | AJ125: =IF('F002'!$G28="NO PELIGROSO",DATOS!$AJ$9,"") | AK125: =IF('F002'!$G28="NO PELIGROSO",DATOS!$AK$9,"") | AL125: =IF('F002'!$G28="NO PELIGROSO",DATOS!$AL$9,"") | AM125: =IF('F002'!$G28="NO PELIGROSO",DATOS!$AM$9,"")
...

Sheet F002
E1: FORMATO 2
E3: MANEJO DE RESIDUOS SOLIDOS: CONTROL DE INGRESO Y SALIDA DE RESIDUOS SÓLIDOS DEL ACR O CMRS
E5: Código: JU-MAP-PRO-003-F002 | I5: Versión: 0
E6: Área: Gerencia de MAP | I6: Fecha: 18-05-2019
A8: ITEM | B8: ACR/CMR | C8: RESPONSABLE DEL ACR/CMRS QUE RECIBE/ENTREGA EL RESIDUO | D8: INGRESO O SALIDA DE RESIDUOS | E8: MOTIVO DE INGRESO O SALIDA DE RESIDUOS | F8: FECHA INGRESO O SALIDA | G8: TIPO DE RESIDUO | H8: NOMBRE DEL RESIDUOS | I8: CANTIDAD INGRESADA O RETIRADA (kg) | J8: EMPRESA QUE GENERÓ/RETIRÓ EL RESIDUO | K8: GERENCIA DE MARCOBRE QUE ENTREGA/RETIRA EL RESIDUO | L8: COMENTARIOS (Indicar a quién se va a Donar, Cómo se va a Reusar o Reciclar / Indicar el tipo de RAEE) | X8: Disposición Final
V9: Papel y cartón | X9: Almacenamiento Temporal
