Workbook

Sheet DATOS
A2: Tipo de acto o cond. | B2: MA | C2: SSO
A4: ACTOS SUBESTÁNDARES (MA) | B4: MAA01. Afectar a la flora/fauna/sitios arqueológicos. | C4: MAA02. Descargar aguas no autorizadas. | D4: MAA03. Generar material particulado (polvo). | E4: MAA04. Generar ruido ambiental molesto. | F4: MAA05. Quemar de residuos. | G4: MAA06. Realizar movimiento de tierras no autorizadas. | H4: MAA07. Realizar trabajos sin evaluación ambiental. | I4: MAA08. Realizar trabajos sin o con controles ambientales deficientes. | J4: MAA09. Regar vías con aguas fuera de los LMP. | K4: MAA10. Segregar incorrectamente los residuos. | L4: MAA11. Transitar por vías no autorizadas. | M4: MAA12. Usar áeras no autorizadas. | N4: MAA13. Usar materiales, herramientas defectuosos. | O4: MAA14. Usar productos químicos no evaluados. | P4: MAA15. Usar vehículos o equipos sin o con kit antiderrame inadecuado. | Q4: MAA16. Otros actos ambientales subestándares. | R4: ************************************ | S4: CONDICIONES SUBESTÁNDARES (MA) | T4: MAC01. Acumulación de residuos en áeras no autorizadas. | U4: MAC02. Almacenamiento Inadecuado de Materiales o Productos. | V4: MAC03. Ausencia de MSDS. | W4: MAC04. Ausencia o mal estado de controles ambientales. | X4: MAC05. Ausencia/inadecuado sistema de contención (Picado, rajado, falta capacidad, etc). | Y4: MAC06. Cilindros o contenedores de residuos complemente llenos. | Z4: MAC07. Cilindros o contenedores de residuos fuera de estándar. | AA4: MAC08. Déficit de cilindros para almacenar residuos. | AB4: MAC09. Emanación de olores desagradables. | AC4: MAC10. Equipo sin mantenimiento preventivo. | AD4: MAC11. Falta de orden y limpieza en el áera de trabajo. | AE4: MAC12. Falta o fuera de estándar del kit antiderrame. | AF4: MAC13. Mangueras/Tuberías en mal estado. | AG4: MAC14. Presencia de animales muertos. | AH4: MAC15. Presencia de derrames en el área de trabajo. | AI4: MAC16. Presencia de material particulado (polvo). | AJ4: MAC17. Presencia de ruido ambiental molesto. | AK4: MAC18. Punto de acopio de residuos sólidos fuera de estándar. | AL4: MAC19. Recipientes con riesgo de desborde. | AM4: MAC20. Residuos mal segregados. | AN4: MAC21. Otras condiciones ambientales subestánadares. | AO4: ACTOS SUBESTÁNDARES (SSO) | AP4: SOA01. Operar equipo sin autorización. | AQ4: SOA02. Operar equipo a velocidad incorrecta. | AR4: SOA03. Señalizar/avisar incorrectamente - No señalizar/avisar. | AS4: SOA04. No Advertir. | AT4: SOA05. Asegurar/bloquear incorrectamente - No asegurar/bloquear. | AU4: SOA06. Desactivar dispositivos de seguridad. | AV4: SOA07. Usar equipos defectuosos. | AW4: SOA08. Usar incorrectamente EPP - No usar EPP. | AX4: SOA09. Instalar carga de manera incorrecta. | AY4: SOA10. Adoptar una ubicación incorrecta. | AZ4: SOA11. Levantar objetos/material incorrectamente. | BA4: SOA12. Adoptar una posición incorrecta para la tarea. | BB4: SOA13. Dar mantenimiento a equipo en operación. | BC4: SOA14. Bromear/Juguetear bruscamente. | BD4: SOA15. Usar equipo incorrectamente. | BE4: SOA16. Trabajar bajo la influencia de alcohol y/o drogas. | BF4: SOA17. Maniobrar incorrectamente. | BG4: SOA18. Realizar otro acto no clasificado. | BH4: ************************************ | BI4: CONDICIONES SUBESTÁNDARES (SSO) | BJ4: SOC01. Guardas, muros de seguridad Inadecuados/No existentes. | BK4: SOC02. Paredes, tejados, pisos, etc. Inestables. | BL4: SOC03. Caminos, pisos, superficies, inadecuados. | BM4: SOC04. Equipo de protección personal inadecuado. | BN4: SOC05. Herramientas, equipos o materiales defectuosos. | BO4: SOC06. Congestión o Acción Restringida. | BP4: SOC07. Sistema de Advertencia/Aviso Inadecuado. | BQ4: SOC08. Peligros de Incendio/Explosión. | BR4: SOC09. Sistema de aseguramiento/bloqueo inadecuado. | BS4: SOC10. Orden y Limpieza deficiente. | BT4: SOC11. Presencia de químicos (polvo, humos, vapor, gas, solventes, etc). | BU4: SOC12. Presencia de Ruido. | BV4: SOC13. Presencia de Radiación. | BW4: SOC14. Temperaturas extremas. | BX4: SOC15. Peligros ergonómicos. | BY4: SOC16. Iluminación deficiente o excesiva. | BZ4: SOC17. Ventilación inadecuada. | CA4: SOC18. Peligros biológicos.
A5: =IF(RAC!$C18="MA",$A$4,"") | B5: =IF(RAC!$C18="MA",B4,"") | C5: =IF(RAC!$C18="MA",C4,"") | D5: =IF(RAC!$C18="MA",D4,"") | E5: =IF(RAC!$C18="MA",E4,"") | F5: =IF(RAC!$C18="MA",F4,"") | G5: =IF(RAC!$C18="MA",G4,"") | H5: =IF(RAC!$C18="MA",H4,"") | I5: =IF(RAC!$C18="MA",I4,"") | ... AN5: =IF(RAC!$C18="MA",AN4,"") | AO5: =IF(RAC!$C18="SSO",AO4,"") -> ACTOS SUBESTÁNDARES (SSO) | AP5: =IF(RAC!$C18="SSO",AP4,"") -> SOA01. Operar equipo sin autorización. | AQ5: =IF(RAC!$C18="SSO",AQ4,"") -> SOA02. Operar equipo a velocidad incorrecta. | AR5: =IF(RAC!$C18="SSO",AR4,"") -> SOA03. Señalizar/avisar incorrectamente - No señalizar/avisar. | AS5: =IF(RAC!$C18="SSO",AS4,"") -> SOA04. No Advertir. | AT5: =IF(RAC!$C18="SSO",AT4,"") -> SOA05. Asegurar/bloquear incorrectamente - No asegurar/bloquear. | AU5: =IF(RAC!$C18="SSO",AU4,"") -> SOA06. Desactivar dispositivos de seguridad. | AV5: =IF(RAC!$C18="SSO",AV4,"") -> SOA07. Usar equipos defectuosos. | ... CA5: =IF(RAC!$C18="SSO",CA4,"") -> SOC18. Peligros biológicos.
A6: Se planteó AC: | B6: Sí | C6: No
A8: Nivel de riesgo: | B8: =IF(RAC!C18="MA","Tolerable","") | C8: =IF(RAC!C18="MA","Alerta","") | D8: =IF(RAC!C18="MA","No aceptable","") | E8: =IF(RAC!C18="SSO","Bajo","") -> Bajo | F8: =IF(RAC!C18="SSO","Medio","") -> Medio | G8: =IF(RAC!C18="SSO","Alto","") -> Alto
A10: Clasificación: | B10: Acto Subestándar | C10: Condición Subestándar
A12: Empresa | D12: Gerencia | I12: Supervisores Medio Ambiente | J12: =IF(RAC!$C$18="MA",I12,"")
A13: ABENGOA | D13: Control de proyectos | I13: ROBERTO ELIAS CARDENAS | J13: =IF(RAC!$C$18="MA",I13,"")
A14: ANGELES | D14: Administración y finanzas (Logística) | I14: CARLOS ALBERTO BERAUN SUSANIBAR | J14: =IF(RAC!$C$18="MA",I14,"")
A15: AMEC FOSTER WHEELER PERU S.A.C. | D15: Adquisiciones y contratos | I15: CESAR ADOLFO GARCIA CHAVEZ | J15: =IF(RAC!$C$18="MA",I15,"")
A16: APC | D16: Auditoría interna | I16: CARLOS ALBERTO AGUIRRE JIMENEZ | J16: =IF(RAC!$C$18="MA",I16,"")
A17: ARCE GEOFÍSICOS | D17: Comisionamiento | I17: CINDY DALINA DAVILA LEYVA | J17: =IF(RAC!$C$18="MA",I17,"")
A18: AUSENCO | D18: Ejecución | I18: RAFAELA DEL CARMEN DELGADO LOAYZA | J18: =IF(RAC!$C$18="MA",I18,"")
A19: CELICOM | D19: Exploraciones | I19: KARLA PATRICIA MONTOYA PERALTA | J19: =IF(RAC!$C$18="MA",I19,"")
A20: CIZCORP | D20: Geología | I20: CARLOS GABRIEL MEGO ARMAS | J20: =IF(RAC!$C$18="MA",I20,"")
A21: CCICSK | D21: Mantenimiento | I21: VICTOR MANUEL SOTO DELGADO | J21: =IF(RAC!$C$18="MA",I21,"")
A22: CLÍNICA INTERNACIONAL | D22: Medio ambiente y permisos | I22: Supervisores Seguridad y Salud Ocupacional | J22: =IF(RAC!$C$18="SSO",I22,"") -> Supervisores Seguridad y Salud Ocupacional
A23: COMIN SAC | D23: Mina | I23: ANGELA ALEJANDRA LOPEZ MEDINA DE ZAVALAGA | J23: =IF(RAC!$C$18="SSO",I23,"") -> ANGELA ALEJANDRA LOPEZ MEDINA DE ZAVALAGA
A24: CRUZ DEL SUR | D24: Operaciones | I24: WALTER ADOLFO LINO MENDEZ | J24: =IF(RAC!$C$18="SSO",I24,"") -> WALTER ADOLFO LINO MENDEZ
A25: DISAL | D25: Planeamiento de mina | I25: CESAR OCTAVIO ALARCON RAMOS | J25: =IF(RAC!$C$18="SSO",I25,"") -> CESAR OCTAVIO ALARCON RAMOS
A26: ECOCENTURY | D26: Procesamiento (Sulfuros, Óxidos, Puerto, Lab. Químico) | I26: ELIZABETH MONTENEGRO SUAREZ | J26: =IF(RAC!$C$18="SSO",I26,"") -> ELIZABETH MONTENEGRO SUAREZ
A27: EXPLOMIN | D27: Recursos humanos (RRHH, SSGG, Security) | I27: EDWIN EDUARDO RIVERO GOMEZ | J27: =IF(RAC!$C$18="SSO",I27,"") -> EDWIN EDUARDO RIVERO GOMEZ
A28: EXSA | D28: Responsabilidad social y comunicaciones | I28: MARLON WILLY BUSCH RUDAS | J28: =IF(RAC!$C$18="SSO",I28,"") -> MARLON WILLY BUSCH RUDAS
A29: FERREYROS | D29: Seguridad y salud | I29: PEDELY CARLOS CLEMENTE VALVAS | J29: =IF(RAC!$C$18="SSO",I29,"") -> PEDELY CARLOS CLEMENTE VALVAS
A30: FIRENO | D30: Gerencia General Marcobre | I30: EDGAR JAIME HIZO GOMERO | J30: =IF(RAC!$C$18="SSO",I30,"") -> EDGAR JAIME HIZO GOMERO
A31: GEOENGINEERING | D31: Legal | I31: CARLOS ALEJANDRO CUBAS DELGADO | J31: =IF(RAC!$C$18="SSO",I31,"") -> CARLOS ALEJANDRO CUBAS DELGADO
A32: GMD S.A. | I32: ROBERTO ERNESTO COBIAN VASQUEZ | J32: =IF(RAC!$C$18="SSO",I32,"") -> ROBERTO ERNESTO COBIAN VASQUEZ
A33: GMI S.A. INGENIEROS CONSULTORES | I33: CARLOS MANUEL HUERTA MEJIA | J33: =IF(RAC!$C$18="SSO",I33,"") -> CARLOS MANUEL HUERTA MEJIA
A34: GOLDER ASSOCIATES | I34: MIGUEL ANGEL CALDERON CARAZA | J34: =IF(RAC!$C$18="SSO",I34,"") -> MIGUEL ANGEL CALDERON CARAZA
A35: GYM
A36: HLC
A37: HIDROBOMBEO INGENIEROS S.A.C
A38: IFLUTECH S.A.C.
A39: Ingenieros Electromecanicos S.A.
A40: INSPECTORATE SERVICES PERU S.A.C.
A41: KILLA URPI S.A.C.
A42: KNIGHT PIESOLD CONSULTORES S.A.
A43: J&V RESGUARDO
A44: LIPLATA
A45: MAKITECH E.I.R.L.
...

Sheet RAC
C2: REPORTE DE ACTO Y CONDICIÓN SUBESTÁNDAR (RAC)
C3: Código: | E3: JU-MAP-PRO-004.F02 | G3: Fecha de emisión: | I3: 43466 | J3: Versión: | K3: 0
C4: Área: Medio Ambiente y Permisos | G4: Registro N°: | H4: 1 | J4: Fecha de elaboración: | L4: 43821
B6: DATOS DEL PERSONAL QUE REPORTA
B8: Nombre y Apellidos: | I8: Área de Marcobre:
B10: Empresa: | I10: Otra empresa:
B12: DESCRIPCIÓN DE LA OBSERVACIÓN
B14: Empresa observada: | H14: Gerencia a la que pertenece (Marcobre):
B16: Ubicación de la observación: | I16: Fecha: | N16: Hora:
B18: Observación SSO/MA: | C18: SSO | F18: Clasificación: | K18: Nivel de Riesgo:
B20: Tipo:
B22: Descripción del acto o condición subestándar:
B24: Medida(s) de control inmediata:
B26: ¿Se planteó una primera acción correctiva?: | E26: Responsable de Marcobre del cierre de la observación: | I26: Fecha de cierre programada: | L26: Supervisor de SSO/MA (Marcobre) a notificar:
B28: Evidencia de la observación: | I28: Evidencia del levantamiento de observación (Cierre de la acción correctiva):
